Workbook
Name _a1: #REF!
Name Print_Title: #REF!

Sheet 表紙
B4: =更新履歴!K4 -> [画面設計]
B7: =更新履歴!K5&CHAR(10) &更新履歴!K6 -> お客さま企業マスタ照会/編集画面
B18: =更新履歴!K1 -> CNレポート作成アプリ「LecMoc」
B21: =更新履歴!K2 -> 2026.12.21
A23: ＜基本設計＞
A24: KS2-4-04_オンラインプロセスフロー.xls | F24: ⇒オンラインプロセスフロー シート
A26: ＜詳細設計＞
A27: SS1-2-02_画面レイアウト.xls | F27: ⇒画面レイアウト シート
A28: SS1-2-04_画面定義書.xls | F28: ⇒画面定義書 シート
A29: SS1-2-05_画面処理内容説明書.xls | F29: ⇒画面処理内容説明書 シート
A30: SS1-2-16_入力項目チェック仕様説明書.xls | F30: ⇒入出力チェック シート

Sheet 更新履歴
A1: =K4 -> [画面設計] | C1: =K5 -> お客さま企業マスタ照会/編集画面 | F1: システム | G1: =K1 -> CNレポート作成アプリ「LecMoc」 | J1: システム | K1: CNレポート作成アプリ「LecMoc」
A2: Ver. | B2: 更新内容 | D2: 対象シート | E2: 実装チケットID | F2: 作成日 | G2: 作成者 | H2: 更新日 | I2: 更新者 | J2: 基本設計作成日 | K2: 2026.12.21
A3: 1.0 | B3: 初版作成 | D3: オンラインプロセスフロー | E3: － | F3: 46377 | G3: 下田
J4: 表紙上段 | K4: [画面設計]
J5: 表紙中段 | K5: お客さま企業マスタ照会/編集画面
J6: 仕様書名
J7: 画面ID | K7: mscs03
J8: 画面名 | K8: =K5 -> お客さま企業マスタ照会/編集画面

Sheet オンラインプロセスフロー
P1: =更新履歴!K2 -> 2026.12.21
A2: オンラインプロセスフロー | AE2: システム | AK2: =更新履歴!K1 -> CNレポート作成アプリ「LecMoc」
AE3: フォーマットNo. | AK3: KS2-4-04/SS2-1-01
A4: 業務プロセスID | K4: LMMVMV03-01 LMMVMV03-02 LMMVMV03-03 | R4: 業務プロセス名 | AB4: 建物マスタ新規登録時の30分値データの自動連携 建物マスタ更新時の30分値データの自動連携 建物マスタ削除時の30分値データの自動連携
A5: 画面ID | K5: =更新履歴!K7 -> mscs03 | R5: 画面名 | AB5: お客さま企業マスタ照会/編集画面
A6: 備 考
A7: お客さま情報を照会、編集する画面

Sheet 画面レイアウト
P1: =更新履歴!K2 -> 2026.12.21
A2: 画面レイアウト | AE2: システム | AK2: =更新履歴!K1 -> CNレポート作成アプリ「LecMoc」
AE3: フォーマットNo. | AK3: SS1-2-02
A4: 画面イメージ
B6: mscs03 お客さま企業マスタ照会/編集画面
C8: 照会画面
AI9: 【編集ボタン】
AI10: 編集画面に切り替える。
AI11: 画面処理内容説明書 No.2
AI13: 【拠点マスタ管理ボタン】
AI14: 拠点マスタ管理画面に遷移する。
C58: 編集画面
AI61: 【拠点情報削除ボタン】
AI62: 該当の拠点を削除する。
AI63: 画面処理内容説明書 No.3
AI65: 【拠点追加ボタン】
AI66: 空の拠点を追加する。
AI67: 画面処理内容説明書 No.5
AI83: 【拠点情報削除ボタン】
AI84: 該当の拠点を削除する。
AI85: 画面処理内容説明書 No.3
AI87: 【選択ボタン】
AI88: 同意書取得組織の選択モーダル表示
AI89: 画面処理内容説明書 No.4
... AI109: 登録ボタン押下時に表示
C122: 同意書取得組織の選択
AI124: 【検索ボタン】
AI125: 組織名で検索を実施する。
AI126: 画面処理内容説明書 No.9

Sheet 画面定義書
F1: =更新履歴!K2 -> 2026.12.21
A3: 画面定義書 | M3: システム | N3: =更新履歴!K1 -> CNレポート作成アプリ「LecMoc」
M4: フォーマットNo. | N4: SS1-2-04
A5: 画面項目No | B5: 画面項目名 | C5: 項目種類 | D5: 書式 | E5: 寄 | F5: 表示/入力条件 | G5: 編集仕様 | H5: イベント | K5: 初期表示 | L5: 項目マッピング | N5: 備考
E6: せ | H6: 発生有無 | I6: イベントNo | J6: イベント名 | K6: 設定値 | L6: TBL・遷移元 | M6: 項目
B7: ＜照会・編集画面＞
A8: =ROW()-2-COUNTBLANK(A$1:A$7) -> 1 | B8: 編集ボタン | C8: ボタン | D8: - | E8: 中 | F8: EP管理者かつ、参照画面であること | H8: 〇 | I8: 2 | J8: 編集切替 | K8: 編集
A9: =ROW()-2-COUNTBLANK(A$1:A$7) -> 2 | B9: お客さま基本情報 | C9: トグル | D9: - | E9: 左 | F9: - | H9: - | I9: - | J9: - | K9: お客さま基本情報
A10: =ROW()-2-COUNTBLANK(A$1:A$7) -> 3 | B10: お客さま名 | C10: ラベル | D10: - | E10: 左 | F10: - | H10: - | I10: - | J10: - | K10: お客さま名
A11: =ROW()-2-COUNTBLANK(A$1:A$7) -> 4 | B11: お客さま名 | C11: テキスト | D11: - | E11: 左 | F11: 初期表示 | H11: - | I11: - | J11: - | L11: 企業基本情報TBL | M11: 企業名
A12: =ROW()-2-COUNTBLANK(A$1:A$7) -> 5 | B12: お客さま名 | C12: テキストボックス | D12: - | E12: 左 | F12: 編集画面 | H12: - | I12: - | J12: - | L12: 企業基本情報TBL | M12: 企業名
A13: =ROW()-2-COUNTBLANK(A$1:A$7) -> 6 | B13: お客さま名（フリガナ） | C13: ラベル | D13: - | E13: 左 | F13: - | H13: - | I13: - | J13: - | K13: お客さま名（フリガナ）
A14: =ROW()-2-COUNTBLANK(A$1:A$7) -> 7 | B14: お客さま名（フリガナ） | C14: テキスト | D14: - | E14: 左 | F14: 照会画面 | H14: - | I14: - | J14: - | L14: 企業基本情報TBL | M14: 企業名（ふりがな）
A15: =ROW()-2-COUNTBLANK(A$1:A$7) -> 8 | B15: お客さま名（フリガナ） | C15: テキストボックス | D15: - | E15: 左 | F15: 編集画面 | H15: - | I15: - | J15: - | L15: 企業基本情報TBL | M15: 企業名（ふりがな）
A16: =ROW()-2-COUNTBLANK(A$1:A$7) -> 9 | B16: 法人番号 | C16: ラベル | D16: - | E16: 左 | F16: - | H16: - | I16: - | J16: - | K16: 法人番号
A17: =ROW()-2-COUNTBLANK(A$1:A$7) -> 10 | B17: 法人番号 | C17: テキスト | D17: - | E17: 左 | F17: 照会画面 | H17: - | I17: - | J17: - | L17: 企業基本情報TBL | M17: 法人番号
A18: =ROW()-2-COUNTBLANK(A$1:A$7) -> 11 | B18: 法人番号 | C18: テキストボックス | D18: - | E18: 左 | F18: 編集画面 | H18: - | I18: - | J18: - | L18: 企業基本情報TBL | M18: 法人番号
A19: =ROW()-2-COUNTBLANK(A$1:A$7) -> 12 | B19: 本社所在地 | C19: ラベル | D19: - | E19: 左 | F19: 照会画面 | H19: - | I19: - | J19: - | K19: 企業所在地
A20: =ROW()-2-COUNTBLANK(A$1:A$7) -> 13 | B20: 本社所在地 | C20: テキスト | D20: - | E20: 左 | F20: 照会画面 | H20: - | I20: - | J20: - | K20: 企業所在地（都道府県） | L20: 企業基本情報TBL | M20: 企業所在地（都道府県） 企業所在地（市区町村以降）
A21: =ROW()-2-COUNTBLANK(A$1:A$7) -> 14 | B21: 本社所在地（都道府県） | C21: ラベル | D21: - | E21: 左 | F21: 編集画面 | H21: - | I21: - | J21: - | K21: 企業所在地（都道府県）
A22: =ROW()-2-COUNTBLANK(A$1:A$7) -> 15 | B22: 本社所在地（都道府県） | C22: セレクトボックス | D22: - | E22: 左 | F22: 編集画面 | H22: - | I22: - | J22: - | L22: 企業基本情報TBL | M22: 企業所在地（都道府県） | N22: 都道府県マスタTBLから一覧を取得して選択する
A23: =ROW()-2-COUNTBLANK(A$1:A$7) -> 16 | B23: 本社所在地（市区町村以降） | C23: ラベル | D23: - | E23: 左 | F23: 編集画面 | H23: - | I23: - | J23: - | K23: 企業所在地（市区町村以降）
A24: =ROW()-2-COUNTBLANK(A$1:A$7) -> 17 | B24: 本社所在地（市区町村以降） | C24: テキストボックス | D24: - | E24: 左 | F24: 編集画面 | H24: - | I24: - | J24: - | L24: 企業基本情報TBL | M24: 企業所在地（市区町村以降）
A25: =ROW()-2-COUNTBLANK(A$1:A$7) -> 18 | B25: 同意書取得経路 | C25: トグル | D25: - | E25: 左 | F25: 拠点情報がない場合、非表示 | H25: - | I25: - | J25: - | K25: 同意書取得経路
A26: =ROW()-2-COUNTBLANK(A$1:A$7) -> 19 | B26: 同意書取得経路 | C26: テキスト | D26: - | E26: 左 | F26: - | G26: 拠点情報に同意書取得経路が含まれない場合、「同意書取得経路が選択されていません。」と表示。 含まれる場合、重複を排除して表示する。 | H26: - | I26: - | J26: - | K26: 備考参照 | L26: 同意書取得経路情報TBL | M26: 同意書取得経路
A27: =ROW()-2-COUNTBLANK(A$1:A$7) -> 20 | B27: 拠点情報 | C27: トグル | D27: - | E27: 左 | F27: - | H27: - | I27: - | J27: - | K27: 拠点情報
A28: =ROW()-2-COUNTBLANK(A$1:A$7) -> 21 | B28: 拠点マスタ管理ボタン | C28: ボタン | D28: - | E28: 中 | F28: 照会画面 | H28: - | I28: - | J28: - | K28: 拠点マスタ管理
A29: =ROW()-2-COUNTBLANK(A$1:A$7) -> 22 | B29: 削除ボタン | C29: ボタン | D29: - | E29: 中 | F29: 編集画面 | H29: 〇 | I29: 3 | J29: 拠点削除
A30: =ROW()-2-COUNTBLANK(A$1:A$7) -> 23 | B30: 拠点名 | C30: ラベル | D30: - | E30: 左 | F30: - | H30: - | I30: - | J30: - | K30: 拠点名
A31: =ROW()-2-COUNTBLANK(A$1:A$7) -> 24 | B31: 拠点名 | C31: テキスト | D31: - | E31: 左 | F31: 照会画面 | H31: - | I31: - | J31: - | L31: 建物マスタTBL | M31: 拠点識別名
A32: =ROW()-2-COUNTBLANK(A$1:A$7) -> 25 | B32: 拠点名 | C32: テキストボックス | D32: - | E32: 左 | F32: 編集画面 | H32: - | I32: - | J32: - | L32: 建物マスタTBL | M32: 拠点識別名
A33: =ROW()-2-COUNTBLANK(A$1:A$7) -> 26 | B33: 拠点所在地 | C33: ラベル | D33: - | E33: 左 | F33: 照会画面 | H33: - | I33: - | J33: - | K33: 拠点所在地
A34: =ROW()-2-COUNTBLANK(A$1:A$7) -> 27 | B34: 拠点所在地 | C34: テキスト | D34: - | E34: 左 | F34: 照会画面 | G34: 拠点所在地（都道府県）＋拠点所在地（市区町村以降） | H34: - | I34: - | J34: - | L34: 建物マスタTBL | M34: 拠点所在地（都道府県） 拠点所在地（市区町村以降）
A35: =ROW()-2-COUNTBLANK(A$1:A$7) -> 28 | B35: 拠点所在地（都道府県） | C35: ラベル | D35: - | E35: 左 | F35: 編集画面 | H35: - | I35: - | J35: - | K35: 拠点所在地（都道府県）
A36: =ROW()-2-COUNTBLANK(A$1:A$7) -> 29 | B36: 拠点所在地（都道府県） | C36: セレクトボックス | D36: - | E36: 左 | F36: 編集画面 | H36: - | I36: - | J36: - | L36: 建物マスタTBL | M36: 拠点所在地（都道府県） | N36: 都道府県マスタTBLから一覧を取得して選択する
A37: =ROW()-2-COUNTBLANK(A$1:A$7) -> 30 | B37: 拠点所在地（市区町村以降） | C37: ラベル | D37: - | E37: 左 | F37: 編集画面 | H37: - | I37: - | J37: - | K37: 拠点所在地（市区町村以降）
A38: =ROW()-2-COUNTBLANK(A$1:A$7) -> 31 | B38: 拠点所在地（市区町村以降） | C38: テキストボックス | D38: - | E38: 左 | F38: 編集画面 | H38: - | I38: - | J38: - | L38: 建物マスタTBL | M38: 拠点所在地（市区町村以降）
A39: =ROW()-2-COUNTBLANK(A$1:A$7) -> 32 | B39: 事業所コード | C39: ラベル | D39: - | E39: 左 | F39: - | H39: - | I39: - | J39: - | K39: 事業所コード
A40: =ROW()-2-COUNTBLANK(A$1:A$7) -> 33 | B40: 事業所コード | C40: テキスト | D40: - | E40: 左 | F40: 照会画面 | H40: - | I40: - | J40: - | L40: 建物マスタTBL | M40: 事業所コード
A41: =ROW()-2-COUNTBLANK(A$1:A$7) -> 34 | B41: 事業所コード | C41: テキストボックス | D41: - | E41: 左 | F41: 編集画面 | H41: - | I41: - | J41: - | L41: 建物マスタTBL | M41: 事業所コード
...

Sheet 画面処理内容説明書
O1: =更新履歴!K2 -> 2026.12.21
A3: 画面処理内容説明書 | AI3: システム | AO3: =更新履歴!K1 -> CNレポート作成アプリ「LecMoc」
AI4: フォーマットNo. | AO4: SS1-2-05
A5: No | B5: イベント名
A6: 1 | B6: 初期表示 | H6: 画面初期表示 | P6: 初期表示時に各種情報を取得してお客さま企業マスタ照会・編集画面を表示する
B8: １．遷移前画面からパラメータを取得
C10: キー | M10: 値 | AB10: 備考
C11: corporate_number | M11: お客さま情報.法人番号
C12: company_name | M12: お客さま情報.企業名
B15: ２．セッション情報をセット
C17: キー | M17: 値 | AB17: 備考
C18: TOKEN | M18: セッション情報.トークン
C19: USER_ID | M19: セッション情報.メールアドレス
C20: ORG_ID | M20: セッション情報.権限情報.組織ID
B22: ３．初期表示画面情報取得
C24: 3.1. 同意書取得経路情報を取得する
C26: LMCNRC-API-12「同意書取得経路取得」を実行する
C27: 入出力構成 | F27: 入力 | H27: 出力 | J27: 名称 | V27: 設定値 | AG27: 備考
F28: － | H28: ○ | J28: 同意書取得区分 | V28: 同意書取得経路取得.同意書取得区分
F29: － | H29: ○ | J29: 同意書取得経路 | V29: 同意書取得経路取得.同意書取得経路
C31: 3.2. 都道府県マスタを取得する
C33: LMEBBD-API-12「都道府県マスタ照会」を実行する
C34: 入出力構成 | F34: 入力 | H34: 出力 | J34: 名称 | V34: 設定値 | AG34: 備考
F35: － | H35: ○ | J35: 都道府県コード | V35: 都道府県マスタ照会.都道府県コード
F36: － | H36: ○ | J36: 都道府県名 | V36: 都道府県マスタ照会.都道府県名
C38: 3.3. 企業データを取得する
C40: LMMBCS-API-03「企業基本情報照会」を実行する
C41: 入出力構成 | F41: 入力 | H41: 出力 | J41: 名称 | V41: 設定値 | AG41: 備考
F42: ○ | H42: － | J42: 法人番号 | V42: お客さま情報.法人番号
F43: － | H43: ○ | J43: 法人番号 | V43: 企業基本情報照会.法人番号
F44: － | H44: ○ | J44: 企業名 | V44: 企業基本情報照会.企業名
F45: － | H45: ○ | J45: 企業名（ふりがな） | V45: 企業基本情報照会.企業名（ふりがな）
F46: － | H46: ○ | J46: 企業所在地（都道府県） | V46: 企業基本情報照会.企業所在地（都道府県）
F47: － | H47: ○ | J47: 企業所在地（市区町村） | V47: 企業基本情報照会.企業所在地（市区町村）
F48: － | H48: ○ | J48: 企業所在地 | V48: 企業基本情報照会.都道府県名
F49: － | H49: ○ | J49: 拠点リスト | V49: 企業基本情報照会.拠点リスト
F50: － | H50: ○ | K50: 同意書取得区分 | V50: 企業基本情報照会.拠点リスト.同意書取得区分
F51: － | H51: ○ | K51: 拠点ID | V51: 企業基本情報照会.拠点リスト.拠点ID
F52: － | H52: ○ | K52: EP事業所コード | V52: 企業基本情報照会.拠点リスト.EP事業所コード
F53: － | H53: ○ | K53: EPお客さまコード | V53: 企業基本情報照会.拠点リスト.EPお客さまコード
...

Sheet 入力項目チェック仕様説明書
Z1: 2026.12.21
A3: 入力項目チェック仕様説明書 | CE3: システム | CL3: CNレポート作成アプリ「LecMoc」
CE4: フォーマットNo. | CL4: SS1-2-16
A5: 項番 | D5: 入力項目名 | M5: 単項目チェック | BR5: その他チェック
M6: 必須 区分 | O6: データ型 | R6: 桁数 | U6: 小数点以下 桁数 | X6: 範囲 | AH6: 許可文字種フラグ | BN6: メッセージ-ID | BR6: エラー種別 区分 | BU6: チェック内容 (項目関連チェック,マスタチェック,データ整合性チェック等) | CS6: メッセージ-ID
X7: 最小値 | AC7: 最大値 | AH7: 半角の場合 | AV7: 全角の場合
AH8: 数値 | AJ8: 英字 小 | AL8: 英字 大 | AN8: カナ | AP8: 空白 | AR8: 記号 | AT8: 改行 | AV8: 数値 | AX8: 英字 小 | AZ8: 英字 大 | BB8: カナ | BD8: かな | BF8: 漢字 | BH8: 空白 | BJ8: 記号 | BL8: 外字
A9: 1 | D9: お客さま名 | M9: 1 | BN9: LMMVMVE0301
O10: N | AC10: 100 | BN10: LMMVMVE0302
D13: お客さま名（フリガナ） | M13: 1 | BN13: LMMVMVE0301
O14: N | AN14: 1 | BB14: 1 | BN14: LMMVMVE0303
AC15: 100 | BN15: LMMVMVE0302
D17: 法人番号 | M17: 1 | BN17: LMMVMVE0301
O18: 9 | R18: 13 | X18: 13 | AC18: 13 | AH18: 1 | BN18: LMMVMVE0302
D21: 本所所在地（都道府県） | M21: 1 | BN21: LMMVMVE0301
D25: 本所所在地（市区町村以降） | M25: 1 | BN25: LMMVMVE0301
O26: N | AC26: 100 | BN26: LMMVMVE0302
D29: 拠点名 | M29: 1 | BN29: LMMVMVE0301
O30: N | AC30: 100 | BN30: LMMVMVE0302
D33: 拠点所在地（都道府県） | M33: 1 | O33: N | BN33: LMMVMVE0301
D37: 拠点所在地（市区町村以降） | M37: 1 | BN37: LMMVMVE0301
O38: N | AC38: 100 | BN38: LMMVMVE0302
D41: 同意書取得経路 | M41: 1 | O41: N | BN41: LMMVMVE0301
D45: 同意書取得組織 | M45: 1 | O45: N | BN45: LMMVMVE0301
D49: 事業所コード | O49: 9 | R49: 3 | X49: 3 | AC49: 3 | AH49: 1 | BN49: LMMVMVE0302
D53: お客さま番号 | O53: 9 | R53: 13 | X53: 13 | AC53: 13 | AH53: 1 | BN53: LMMVMVE0302
D57: 供給地点特定番号 | O57: 9 | R57: 22 | X57: 22 | AC57: 22 | AH57: 1 | BN57: LMMVMVE0302
