Workbook
Name __________a1: #REF!
Name __________a1: #REF!
Name _________a1: #REF!
Name _________a1: #REF!
Name ________a1: #REF!
Name _______a1: #REF!
Name ______a1: #REF!
Name _____a1: #REF!
Name ____a1: #REF!
Name ___a1: #REF!
Name __a1: #REF!
Name _a1: #REF!
Name A_農業_林業: #REF!
Name A_農業_林業: #REF!
Name A_農業_林業: #REF!
Name A_農業_林業: #REF!
Name A_農業_林業: #REF!
Name A_農業_林業: #REF!
Name A_農業_林業: #REF!
Name A_農業_林業: #REF!
Name A_農業_林業: #REF!
Name A_農業_林業: #REF!
Name A_農業_林業: #REF!
Name A_農業_林業: #REF!
Name A_農業_林業: #REF!
Name A_農業_林業: #REF!
Name A_農業_林業: #REF!
Name A_農業_林業: #REF!
Name A_農業_林業: #REF!
Name A_農業_林業: #REF!
Name A_農業_林業: #REF!
Name A_農業_林業: #REF!
Name A_農業_林業: #REF!
Name A_農業_林業: #REF!
Name A_農業_林業: #REF!
Name A_農業_林業: #REF!
Name A_農業_林業: #REF!
Name A_農業_林業: #REF!
Name A_農業_林業: #REF!
Name A_農業_林業: #REF!
Name A_農業_林業: #REF!
Name A_農業_林業: #REF!
Name A_農業_林業: #REF!
Name A_農業_林業: #REF!
Name A_農業_林業: #REF!
Name A_農業_林業: #REF!
Name A_農業_林業: #REF!
Name A_農業_林業: #REF!
Name A_農業_林業: #REF!
Name A_農業_林業: #REF!
Name A_農業_林業: #REF!
Name A_農業_林業: #REF!
Name A_農業_林業: #REF!
Name A_農業_林業: #REF!
Name A_農業_林業: #REF!
Name A_農業_林業: #REF!
Name A_農業_林業: #REF!
Name A_農業_林業: #REF!
Name A_農業_林業: #REF!
Name A_農業_林業: #REF!

Sheet 修正履歴
D1: =E7 -> 2026/12/21
A5: No | B5: Ver. | C5: 修正箇所 | D5: 修正内容 | E5: 更新日時 | F5: 備考
A6: 1 | D6: 社外向けとして再定義 | E6: 2026/3/26
A7: 2 | C7: STEP4開発 | D7: STEP4開発に手追加 | E7: 2026/12/21
A8: 3 | C8: 【step3残対応】 月別建物エネルギー集計情報 | D8: PKを部分ユニーク制約に変更し、供給メニューをユニーク制約に追加する | E8: 2026/9/24

Sheet ER図

Sheet SS2-3-05_テーブル一覧
E1: =修正履歴!E7 -> 2026/12/21
D2: ※STEP3のテーブルはPostgre、Hiveの両方に格納する
A3: テーブル一覧
A5: No | B5: 区分 | C5: 格納先 | D5: テーブル名 | E5: テーブル概要 | F5: 備考
A6: 1 | B6: マスタ | C6: PostgreSQL | D6: ユーザー情報 | E6: システム利用のユーザー情報
A7: =A6+1 -> 2 | B7: トラン | C7: PostgreSQL | D7: 最終ログイン情報 | E7: 最終ログイン日時を管理する情報
A8: =A7+1 -> 3 | B8: トラン | C8: PostgreSQL | D8: セッション情報 | E8: ログイン時のセッションID情報管理する
A9: =A8+1 -> 4 | B9: マスタ | C9: PostgreSQL | D9: 利用者組織情報 | E9: システム利用各ユーザーの所属組織の定義情報
A10: =A9+1 -> 5 | B10: トラン | C10: PostgreSQL | D10: ユーザー別利用状況 | E10: システム利用各ユーザーの操作履歴情報
A11: =A10+1 -> 6 | B11: トラン | C11: PostgreSQL | D11: 操作履歴情報 | E11: 企業別のレポート関連操作履歴情報
A12: =A11+1 -> 7 | B12: トラン | C12: PostgreSQL | D12: お知らせ | E12: システム管理者が登録するお知らせ情報
A13: =A12+1 -> 8 | B13: トラン | C13: PostgreSQL | D13: 30分値の生データ情報 | E13: 電力消費や発電に関する30分単位のデータ情報 | F13: STEP4改修
A14: =A13+1 -> 9 | B14: トラン | C14: PostgreSQL | D14: Scope3集計情報 | E14: 地銀単位にCO2排出量を集計する情報
A15: =A14+1 -> 10 | B15: トラン | C15: PostgreSQL | D15: 可視化事業者ヒアリングデータの生データ情報 | E15: 可視化事業者から取得ヒアリング情報
A16: =A15+1 -> 11 | B16: トラン | C16: PostgreSQL | D16: CN対策実施申込情報 | E16: 入力シートの生データを蓄積するための情報
A17: =A16+1 -> 12 | B17: マスタ | C17: PostgreSQL | D17: 企業基本情報マスタ | E17: CN実施の企業基本情報
A18: =A17+1 -> 13 | B18: マスタ | C18: PostgreSQL | D18: 企業詳細情報マスタ | E18: CN実施の企業詳細情報
A19: =A18+1 -> 14 | B19: トラン | C19: PostgreSQL | D19: 建物情報 | E19: CN実施企業の建物情報
A20: =A19+1 -> 15 | B20: マスタ | C20: PostgreSQL | D20: 建物マスタ | E20: CN実施企業の建物マスタ情報
A21: =A20+1 -> 16 | B21: トラン | C21: PostgreSQL | D21: レポート格納情報 | E21: 生成されているレポートPDFファイルの格納情報
A22: =A21+1 -> 17 | B22: トラン | C22: PostgreSQL | D22: 可視化事業者受領エネルギーの生データ情報（JFS） | E22: JFSから提供されるエネルギー情報
A23: =A22+1 -> 18 | B23: トラン | C23: PostgreSQL | D23: 可視化事業者共通エネルギー格納情報 | E23: 変換処理後の生データ
A24: =A23+1 -> 19 | B24: トラン | C24: PostgreSQL | D24: 欠損一覧情報 | E24: 欠損一覧の情報
A25: =A24+1 -> 20 | B25: トラン | C25: PostgreSQL | D25: KPI一覧情報 | E25: KPI一覧の情報
A26: =A25+1 -> 21 | B26: 共通 | C26: Hive | D26: 日本標準産業分類マスタ | E26: 国が発表する日本産業の分類情報
A27: =A26+1 -> 22 | B27: 共通 | C27: Hive | D27: 活動項目小分類（事業者）マスタ | E27: 活動項目小分類（事業者）の換算係数や排出係数情報 | F27: 換算係数マスタの位置づけ
A28: =A27+1 -> 23 | B28: マスタ | C28: PostgreSQL | D28: 電力会社排出係数マスタ | E28: 国が発表する電力会社のCO2排出係数情報 | F28: 電気事業者調整後排出係数マスタ
A29: =A28+1 -> 24 | B29: マスタ | C29: PostgreSQL | D29: エリア情報マスタ | E29: CN実施企業の建物群情報
A30: =A29+1 -> 25 | B30: マスタ | C30: PostgreSQL | D30: 建物グループマスタ | E30: CN実施企業のグループ情報
A31: =A30+1 -> 26 | B31: トラン | C31: PostgreSQL | D31: 年度別建物エネルギー集計情報 | E31: 年度別の建物毎のエネルギー利用情報
A32: =A31+1 -> 27 | B32: トラン | C32: PostgreSQL | D32: 年度別法人エネルギー集計情報 | E32: 年度別の法人毎のエネルギー利用情報
A33: =A32+1 -> 28 | B33: トラン | C33: PostgreSQL | D33: 月別建物エネルギー集計情報 | E33: 月別の建物毎のエネルギー利用情報
A34: =A33+1 -> 29 | B34: トラン | C34: PostgreSQL | D34: 月別法人エネルギー集計情報 | E34: 月別の法人毎のエネルギー利用情報
A35: =A34+1 -> 30 | B35: マスタ | C35: PostgreSQL | D35: 算定ロジックマスタ | E35: マスタデータの係数に依存されている算定ロジックを管理する
A36: =A35+1 -> 31 | B36: トラン | C36: PostgreSQL | D36: CNレポート情報 | E36: CNレポートを表示するための計算結果情報
A37: =A36+1 -> 32 | B37: トラン | C37: PostgreSQL | D37: 電力使用状況見える化レポート | E37: 電力使用状況見える化レポートを表示するための計算結果情報
A38: =A37+1 -> 33 | B38: マスタ | C38: PostgreSQL | D38: 法人コード情報マスタ | E38: 共通用コードマスタ情報
A39: =A38+1 -> 34 | B39: トラン | C39: PostgreSQL | D39: フォーマット格納情報 | E39: 各種フォーマット出力画面でダウンロードする各種ファイル
A40: =A39+1 -> 35 | B40: マスタ | C40: PostgreSQL | D40: 公表ベンチマークデータ情報 | E40: 公表ベンチマークデータ情報
... A45: =A44+1 -> 40 | B45: マスタ | C45: PostgreSQL | D45: 組織権限情報 | E45: 組織別画面に対する権限情報
...

Sheet SS2-3-04_物理データモデル

Sheet SS2-3-06_テーブル定義書→

Sheet 担当者別電力見える化レポート管理情報
D1: =修正履歴!E7 -> 2026/12/21
A2: テーブル名（日本語） | D2: システム名 | I2: 作成者 | J2: 承認者 | K2: 作成日
A3: 担当者別電力見える化レポート管理情報 | D3: CNレポート作成アプリ「LecMoc」
A4: テーブル名（英語） | D4: スキーマ | I4: 更新者 | J4: 承認者 | K4: 更新日
A5: T_USER_POWER_REPORT_MNG_INFO | D5: DB_CORP
L6: PRIMARY_KEYS
A7: No | B7: 論理名 | C7: 物理名 | D7: 型 | E7: 長さ | F7: 精度 | G7: 必須 | H7: 主キー（PK） | I7: 備考 | L7: ="drop TABLE IF EXISTS db_corp."&A5&" CASCADE;" -> drop TABLE IF EXISTS db_corp.T_USER_POWER_REPORT_MNG_INFO CASCADE;
A8: 1 | B8: ファイルID | C8: FILE_ID | D8: SERIAL | E8: - | F8: - | G8: 〇 | H8: 1 | L8: ="CREATE TABLE IF NOT EXISTS db_corp."&A5&" (" -> CREATE TABLE IF NOT EXISTS db_corp.T_USER_POWER_REPORT_MNG_INFO (
A9: =A8+1 -> 2 | B9: ファイル名 | C9: FILE_NAME | D9: VARCHAR | E9: 255 | F9: - | L9: {=IF(B8="", IF($L$6="PRIMARY_KEYS", ",PRIMARY KEY ("&_xlfn.TEXTJOIN(", ", TRUE, $C$8)&")" & CHAR(10) & ");", ");" ), " "&C8&" "&D8& _xlfn.IFS( E8="-", "", OR(D8="TIMESTAMP", D8="SMALLINT"), E8&IF(F8<>"-", ","&F8, ""), TRUE, "("&E8&IF(F8<>"-", ","&F8, "")&")" )& IF(G8<>"", " NOT NULL", "")& IF(H8<>"", ",", IF(B9<>"", ",", "") )& " -- "&B8 )} -> FILE_ID SERIAL NOT NULL, -- ファイルID
A10: =A9+1 -> 3 | B10: ファイルパス | C10: FILE_PATH | D10: VARCHAR | E10: 255 | F10: - | L10: {=IF(B9="", IF($L$6="PRIMARY_KEYS", ",PRIMARY KEY ("&_xlfn.TEXTJOIN(", ", TRUE, $C$8)&")" & CHAR(10) & ");", ");" ), " "&C9&" "&D9& _xlfn.IFS( E9="-", "", OR(D9="TIMESTAMP", D9="SMALLINT"), E9&IF(F9<>"-", ","&F9, ""), TRUE, "("&E9&IF(F9<>"-", ","&F9, "")&")" )& IF(G9<>"", " NOT NULL", "")& IF(H9<>"", ",", IF(B10<>"", ",", "") )& " -- "&B9 )} -> FILE_NAME VARCHAR(255), -- ファイル名
A11: =A10+1 -> 4 | B11: ファイル作成日時 | C11: FILE_CREATED_AT | D11: TIMESTAMP | E11: - | F11: - | I11: ファイル作成完了日時。YYYYMMDDHHMM | L11: {=IF(B10="", IF($L$6="PRIMARY_KEYS", ",PRIMARY KEY ("&_xlfn.TEXTJOIN(", ", TRUE, $C$8)&")" & CHAR(10) & ");", ");" ), " "&C10&" "&D10& _xlfn.IFS( E10="-", "", OR(D10="TIMESTAMP", D10="SMALLINT"), E10&IF(F10<>"-", ","&F10, ""), TRUE, "("&E10&IF(F10<>"-", ","&F10, "")&")" )& IF(G10<>"", " NOT NULL", "")& IF(H10<>"", ",", IF(B11<>"", ",", "") )& " -- "&B10 )} -> FILE_PATH VARCHAR(255), -- ファイルパス
A12: =A11+1 -> 5 | B12: 作成状態 | C12: CREATE_STATUS | D12: VARCHAR | E12: 1 | F12: - | I12: 1:作成依頼 2:作成中 3:完了4:完了（警告）5:エラー | L12: {=IF(B11="", IF($L$6="PRIMARY_KEYS", ",PRIMARY KEY ("&_xlfn.TEXTJOIN(", ", TRUE, $C$8)&")" & CHAR(10) & ");", ");" ), " "&C11&" "&D11& _xlfn.IFS( E11="-", "", OR(D11="TIMESTAMP", D11="SMALLINT"), E11&IF(F11<>"-", ","&F11, ""), TRUE, "("&E11&IF(F11<>"-", ","&F11, "")&")" )& IF(G11<>"", " NOT NULL", "")& IF(H11<>"", ",", IF(B12<>"", ",", "") )& " -- "&B11 )} -> FILE_CREATED_AT TIMESTAMP, -- ファイル作成日時
A13: =A12+1 -> 6 | B13: 組織ID(FK) | C13: ORG_ID | D13: VARCHAR | E13: 20 | F13: - | G13: 〇 | L13: {=IF(B12="", IF($L$6="PRIMARY_KEYS", ",PRIMARY KEY ("&_xlfn.TEXTJOIN(", ", TRUE, $C$8)&")" & CHAR(10) & ");", ");" ), " "&C12&" "&D12& _xlfn.IFS( E12="-", "", OR(D12="TIMESTAMP", D12="SMALLINT"), E12&IF(F12<>"-", ","&F12, ""), TRUE, "("&E12&IF(F12<>"-", ","&F12, "")&")" )& IF(G12<>"", " NOT NULL", "")& IF(H12<>"", ",", IF(B13<>"", ",", "") )& " -- "&B12 )} -> CREATE_STATUS VARCHAR(1), -- 作成状態
A14: =A13+1 -> 7 | B14: 担当組織 | C14: USER_ORG_NAME | D14: VARCHAR | E14: 1300 | F14: - | G14: 〇 | L14: {=IF(B13="", IF($L$6="PRIMARY_KEYS", ",PRIMARY KEY ("&_xlfn.TEXTJOIN(", ", TRUE, $C$8)&")" & CHAR(10) & ");", ");" ), " "&C13&" "&D13& _xlfn.IFS( E13="-", "", OR(D13="TIMESTAMP", D13="SMALLINT"), E13&IF(F13<>"-", ","&F13, ""), TRUE, "("&E13&IF(F13<>"-", ","&F13, "")&")" )& IF(G13<>"", " NOT NULL", "")& IF(H13<>"", ",", IF(B14<>"", ",", "") )& " -- "&B13 )} -> ORG_ID VARCHAR(20) NOT NULL, -- 組織ID(FK)
A15: =A14+1 -> 8 | B15: 顧客担当者 | C15: SALES_USER_NAME | D15: VARCHAR | E15: 1300 | F15: - | G15: 〇 | L15: {=IF(B14="", IF($L$6="PRIMARY_KEYS", ",PRIMARY KEY ("&_xlfn.TEXTJOIN(", ", TRUE, $C$8)&")" & CHAR(10) & ");", ");" ), " "&C14&" "&D14& _xlfn.IFS( E14="-", "", OR(D14="TIMESTAMP", D14="SMALLINT"), E14&IF(F14<>"-", ","&F14, ""), TRUE, "("&E14&IF(F14<>"-", ","&F14, "")&")" )& IF(G14<>"", " NOT NULL", "")& IF(H14<>"", ",", IF(B15<>"", ",", "") )& " -- "&B14 )} -> USER_ORG_NAME VARCHAR(1300) NOT NULL, -- 担当組織
A16: =A15+1 -> 9 | B16: 対象年月 | C16: TARGET_YEAR_MONTH | D16: VARCHAR | E16: 6 | F16: - | G16: 〇 | L16: {=IF(B15="", IF($L$6="PRIMARY_KEYS", ",PRIMARY KEY ("&_xlfn.TEXTJOIN(", ", TRUE, $C$8)&")" & CHAR(10) & ");", ");" ), " "&C15&" "&D15& _xlfn.IFS( E15="-", "", OR(D15="TIMESTAMP", D15="SMALLINT"), E15&IF(F15<>"-", ","&F15, ""), TRUE, "("&E15&IF(F15<>"-", ","&F15, "")&")" )& IF(G15<>"", " NOT NULL", "")& IF(H15<>"", ",", IF(B16<>"", ",", "") )& " -- "&B15 )} -> SALES_USER_NAME VARCHAR(1300) NOT NULL, -- 顧客担当者
A17: =A16+1 -> 10 | B17: 省エネサポートサービス加入フラグ | C17: SYOUSAPO_FLG | D17: BOOLEAN | E17: - | F17: - | G17: 〇 | I17: デフォルト「FALSE」 | L17: {=IF(B16="", IF($L$6="PRIMARY_KEYS", ",PRIMARY KEY ("&_xlfn.TEXTJOIN(", ", TRUE, $C$8)&")" & CHAR(10) & ");", ");" ), " "&C16&" "&D16& _xlfn.IFS( E16="-", "", OR(D16="TIMESTAMP", D16="SMALLINT"), E16&IF(F16<>"-", ","&F16, ""), TRUE, "("&E16&IF(F16<>"-", ","&F16, "")&")" )& IF(G16<>"", " NOT NULL", "")& IF(H16<>"", ",", IF(B17<>"", ",", "") )& " -- "&B16 )} -> TARGET_YEAR_MONTH VARCHAR(6) NOT NULL, -- 対象年月
A18: =A17+1 -> 11 | B18: 作成者 | C18: CREATED_BY | D18: VARCHAR | E18: 50 | F18: - | G18: 〇 | L18: {=IF(B17="", IF($L$6="PRIMARY_KEYS", ",PRIMARY KEY ("&_xlfn.TEXTJOIN(", ", TRUE, $C$8)&")" & CHAR(10) & ");", ");" ), " "&C17&" "&D17& _xlfn.IFS( E17="-", "", OR(D17="TIMESTAMP", D17="SMALLINT"), E17&IF(F17<>"-", ","&F17, ""), TRUE, "("&E17&IF(F17<>"-", ","&F17, "")&")" )& IF(G17<>"", " NOT NULL", "")& IF(H17<>"", ",", IF(B18<>"", ",", "") )& " -- "&B17 )} -> SYOUSAPO_FLG BOOLEAN NOT NULL, -- 省エネサポートサービス加入フラグ
A19: =A18+1 -> 12 | B19: 作成日時 | C19: CREATED_AT | D19: TIMESTAMP | E19: - | F19: - | G19: 〇 | I19: レコード作成日時 | L19: {=IF(B18="", IF($L$6="PRIMARY_KEYS", ",PRIMARY KEY ("&_xlfn.TEXTJOIN(", ", TRUE, $C$8)&")" & CHAR(10) & ");", ");" ), " "&C18&" "&D18& _xlfn.IFS( E18="-", "", OR(D18="TIMESTAMP", D18="SMALLINT"), E18&IF(F18<>"-", ","&F18, ""), TRUE, "("&E18&IF(F18<>"-", ","&F18, "")&")" )& IF(G18<>"", " NOT NULL", "")& IF(H18<>"", ",", IF(B19<>"", ",", "") )& " -- "&B18 )} -> CREATED_BY VARCHAR(50) NOT NULL, -- 作成者
A20: =A19+1 -> 13 | B20: 更新者 | C20: UPDATED_BY | D20: VARCHAR | E20: 50 | F20: - | L20: {=IF(B19="", IF($L$6="PRIMARY_KEYS", ",PRIMARY KEY ("&_xlfn.TEXTJOIN(", ", TRUE, $C$8)&")" & CHAR(10) & ");", ");" ), " "&C19&" "&D19& _xlfn.IFS( E19="-", "", OR(D19="TIMESTAMP", D19="SMALLINT"), E19&IF(F19<>"-", ","&F19, ""), TRUE, "("&E19&IF(F19<>"-", ","&F19, "")&")" )& IF(G19<>"", " NOT NULL", "")& IF(H19<>"", ",", IF(B20<>"", ",", "") )& " -- "&B19 )} -> CREATED_AT TIMESTAMP NOT NULL, -- 作成日時
A21: =A20+1 -> 14 | B21: 更新日時 | C21: UPDATED_AT | D21: TIMESTAMP | E21: - | F21: - | I21: レコード更新日時 | L21: {=IF(B20="", IF($L$6="PRIMARY_KEYS", ",PRIMARY KEY ("&_xlfn.TEXTJOIN(", ", TRUE, $C$8)&")" & CHAR(10) & ");", ");" ), " "&C20&" "&D20& _xlfn.IFS( E20="-", "", OR(D20="TIMESTAMP", D20="SMALLINT"), E20&IF(F20<>"-", ","&F20, ""), TRUE, "("&E20&IF(F20<>"-", ","&F20, "")&")" )& IF(G20<>"", " NOT NULL", "")& IF(H20<>"", ",", IF(B21<>"", ",", "") )& " -- "&B20 )} -> UPDATED_BY VARCHAR(50), -- 更新者
L22: {=IF(B21="", IF($L$6="PRIMARY_KEYS", ",PRIMARY KEY ("&_xlfn.TEXTJOIN(", ", TRUE, $C$8)&")" & CHAR(10) & ");", ");" ), " "&C21&" "&D21& _xlfn.IFS( E21="-", "", OR(D21="TIMESTAMP", D21="SMALLINT"), E21&IF(F21<>"-", ","&F21, ""), TRUE, "("&E21&IF(F21<>"-", ","&F21, "")&")" )& IF(G21<>"", " NOT NULL", "")& IF(H21<>"", ",", IF(B22<>"", ",", "") )& " -- "&B21 )} -> UPDATED_AT TIMESTAMP -- 更新日時
L23: {=IF(B22="", IF($L$6="PRIMARY_KEYS", ",PRIMARY KEY ("&_xlfn.TEXTJOIN(", ", TRUE, $C$8)&")" & CHAR(10) & ");", ");" ), " "&C22&" "&D22& _xlfn.IFS( E22="-", "", OR(D22="TIMESTAMP", D22="SMALLINT"), E22&IF(F22<>"-", ","&F22, ""), TRUE, "("&E22&IF(F22<>"-", ","&F22, "")&")" )& IF(G22<>"", " NOT NULL", "")& IF(H22<>"", ",", IF(B23<>"", ",", "") )& " -- "&B22 )} -> ,PRIMARY KEY (FILE_ID) );
L25: ="COMMENT ON TABLE db_corp." & A5 & " IS '" & A3 & "';" -> COMMENT ON TABLE db_corp.T_USER_POWER_REPORT_MNG_INFO IS '担当者別電力見える化レポート管理情報';
L26: ="COMMENT ON COLUMN db_corp." & $A$5&"."&C8&" IS '" &B8&"';" -> COMMENT ON COLUMN db_corp.T_USER_POWER_REPORT_MNG_INFO.FILE_ID IS 'ファイルID';
L27: ="COMMENT ON COLUMN db_corp." & $A$5&"."&C9&" IS '" &B9&"';" -> COMMENT ON COLUMN db_corp.T_USER_POWER_REPORT_MNG_INFO.FILE_NAME IS 'ファイル名';
L28: ="COMMENT ON COLUMN db_corp." & $A$5&"."&C10&" IS '" &B10&"';" -> COMMENT ON COLUMN db_corp.T_USER_POWER_REPORT_MNG_INFO.FILE_PATH IS 'ファイルパス';
L29: ="COMMENT ON COLUMN db_corp." & $A$5&"."&C11&" IS '" &B11&"';" -> COMMENT ON COLUMN db_corp.T_USER_POWER_REPORT_MNG_INFO.FILE_CREATED_AT IS 'ファイル作成日時';
L30: ="COMMENT ON COLUMN db_corp." & $A$5&"."&C12&" IS '" &B12&"';" -> COMMENT ON COLUMN db_corp.T_USER_POWER_REPORT_MNG_INFO.CREATE_STATUS IS '作成状態';
L31: ="COMMENT ON COLUMN db_corp." & $A$5&"."&C13&" IS '" &B13&"';" -> COMMENT ON COLUMN db_corp.T_USER_POWER_REPORT_MNG_INFO.ORG_ID IS '組織ID(FK)';
L32: ="COMMENT ON COLUMN db_corp." & $A$5&"."&C14&" IS '" &B14&"';" -> COMMENT ON COLUMN db_corp.T_USER_POWER_REPORT_MNG_INFO.USER_ORG_NAME IS '担当組織';
L33: ="COMMENT ON COLUMN db_corp." & $A$5&"."&C15&" IS '" &B15&"';" -> COMMENT ON COLUMN db_corp.T_USER_POWER_REPORT_MNG_INFO.SALES_USER_NAME IS '顧客担当者';
L34: ="COMMENT ON COLUMN db_corp." & $A$5&"."&C16&" IS '" &B16&"';" -> COMMENT ON COLUMN db_corp.T_USER_POWER_REPORT_MNG_INFO.TARGET_YEAR_MONTH IS '対象年月';
L35: ="COMMENT ON COLUMN db_corp." & $A$5&"."&C17&" IS '" &B17&"';" -> COMMENT ON COLUMN db_corp.T_USER_POWER_REPORT_MNG_INFO.SYOUSAPO_FLG IS '省エネサポートサービス加入フラグ';
L36: ="COMMENT ON COLUMN db_corp." & $A$5&"."&C18&" IS '" &B18&"';" -> COMMENT ON COLUMN db_corp.T_USER_POWER_REPORT_MNG_INFO.CREATED_BY IS '作成者';
L37: ="COMMENT ON COLUMN db_corp." & $A$5&"."&C19&" IS '" &B19&"';" -> COMMENT ON COLUMN db_corp.T_USER_POWER_REPORT_MNG_INFO.CREATED_AT IS '作成日時';
... L39: ="COMMENT ON COLUMN db_corp." & $A$5&"."&C21&" IS '" &B21&"';" -> COMMENT ON COLUMN db_corp.T_USER_POWER_REPORT_MNG_INFO.UPDATED_AT IS '更新日時';

Sheet 電力見える化レポート管理情報
D1: =修正履歴!E7 -> 2026/12/21
A2: テーブル名（日本語） | D2: システム名 | I2: 作成者 | J2: 承認者 | K2: 作成日
A3: 電力見える化レポート管理情報 | D3: CNレポート作成アプリ「LecMoc」
A4: テーブル名（英語） | D4: スキーマ | I4: 更新者 | J4: 承認者 | K4: 更新日
A5: T_POWER_REPORT_MNG_INFO | D5: DB_CORP
L6: PRIMARY_KEYS
A7: No | B7: 論理名 | C7: 物理名 | D7: 型 | E7: 長さ | F7: 精度 | G7: 必須 | H7: 主キー（PK） | I7: 備考 | L7: ="drop TABLE IF EXISTS db_corp."&A5&" CASCADE;" -> drop TABLE IF EXISTS db_corp.T_POWER_REPORT_MNG_INFO CASCADE;
A8: 1 | B8: 供給地点特定番号(FK) | C8: SUPPLY_POINT_NUMBER | D8: VARCHAR | E8: 27 | F8: - | G8: 〇 | H8: 1 | L8: ="CREATE TABLE IF NOT EXISTS db_corp."&A5&" (" -> CREATE TABLE IF NOT EXISTS db_corp.T_POWER_REPORT_MNG_INFO (
A9: =A8+1 -> 2 | B9: 対象年月 | C9: TARGET_YEAR_MONTH | D9: VARCHAR | E9: 6 | F9: - | G9: 〇 | H9: 2 | L9: {=IF(B8="", IF($L$6="PRIMARY_KEYS", ",PRIMARY KEY ("&_xlfn.TEXTJOIN(", ", TRUE, $C$8)&")" & CHAR(10) & ");", ");" ), " "&C8&" "&D8& _xlfn.IFS( E8="-", "", OR(D8="TIMESTAMP", D8="SMALLINT"), E8&IF(F8<>"-", ","&F8, ""), TRUE, "("&E8&IF(F8<>"-", ","&F8, "")&")" )& IF(G8<>"", " NOT NULL", "")& IF(H8<>"", ",", IF(B9<>"", ",", "") )& " -- "&B8 )} -> SUPPLY_POINT_NUMBER VARCHAR(27) NOT NULL, -- 供給地点特定番号(FK)
A10: =A9+1 -> 3 | B10: 企業ID | C10: COMPANY_ID | D10: VARCHAR | E10: 14 | F10: - | L10: {=IF(B9="", IF($L$6="PRIMARY_KEYS", ",PRIMARY KEY ("&_xlfn.TEXTJOIN(", ", TRUE, $C$8)&")" & CHAR(10) & ");", ");" ), " "&C9&" "&D9& _xlfn.IFS( E9="-", "", OR(D9="TIMESTAMP", D9="SMALLINT"), E9&IF(F9<>"-", ","&F9, ""), TRUE, "("&E9&IF(F9<>"-", ","&F9, "")&")" )& IF(G9<>"", " NOT NULL", "")& IF(H9<>"", ",", IF(B10<>"", ",", "") )& " -- "&B9 )} -> TARGET_YEAR_MONTH VARCHAR(6) NOT NULL, -- 対象年月
A11: =A10+1 -> 4 | B11: 省エネサポートサービス加入フラグ | C11: SYOUSAPO_FLG | D11: BOOLEAN | E11: - | F11: - | G11: 〇 | I11: デフォルト「FALSE」 | L11: {=IF(B10="", IF($L$6="PRIMARY_KEYS", ",PRIMARY KEY ("&_xlfn.TEXTJOIN(", ", TRUE, $C$8)&")" & CHAR(10) & ");", ");" ), " "&C10&" "&D10& _xlfn.IFS( E10="-", "", OR(D10="TIMESTAMP", D10="SMALLINT"), E10&IF(F10<>"-", ","&F10, ""), TRUE, "("&E10&IF(F10<>"-", ","&F10, "")&")" )& IF(G10<>"", " NOT NULL", "")& IF(H10<>"", ",", IF(B11<>"", ",", "") )& " -- "&B10 )} -> COMPANY_ID VARCHAR(14), -- 企業ID
A12: =A11+1 -> 5 | B12: ファイル名 | C12: FILE_NAME | D12: VARCHAR | E12: 255 | F12: - | L12: {=IF(B11="", IF($L$6="PRIMARY_KEYS", ",PRIMARY KEY ("&_xlfn.TEXTJOIN(", ", TRUE, $C$8)&")" & CHAR(10) & ");", ");" ), " "&C11&" "&D11& _xlfn.IFS( E11="-", "", OR(D11="TIMESTAMP", D11="SMALLINT"), E11&IF(F11<>"-", ","&F11, ""), TRUE, "("&E11&IF(F11<>"-", ","&F11, "")&")" )& IF(G11<>"", " NOT NULL", "")& IF(H11<>"", ",", IF(B12<>"", ",", "") )& " -- "&B11 )} -> SYOUSAPO_FLG BOOLEAN NOT NULL, -- 省エネサポートサービス加入フラグ
A13: =A12+1 -> 6 | B13: レポート作成年月日 | C13: REPORT_CREATED_AT | D13: TIMESTAMP | E13: - | F13: - | L13: {=IF(B12="", IF($L$6="PRIMARY_KEYS", ",PRIMARY KEY ("&_xlfn.TEXTJOIN(", ", TRUE, $C$8)&")" & CHAR(10) & ");", ");" ), " "&C12&" "&D12& _xlfn.IFS( E12="-", "", OR(D12="TIMESTAMP", D12="SMALLINT"), E12&IF(F12<>"-", ","&F12, ""), TRUE, "("&E12&IF(F12<>"-", ","&F12, "")&")" )& IF(G12<>"", " NOT NULL", "")& IF(H12<>"", ",", IF(B13<>"", ",", "") )& " -- "&B12 )} -> FILE_NAME VARCHAR(255), -- ファイル名
A14: =A13+1 -> 7 | B14: 作成状態 | C14: CREATE_STATUS | D14: VARCHAR | E14: 1 | F14: - | G14: 〇 | I14: 1:作成依頼 2:作成中 3:完了4:完了（警告）5:エラー | L14: {=IF(B13="", IF($L$6="PRIMARY_KEYS", ",PRIMARY KEY ("&_xlfn.TEXTJOIN(", ", TRUE, $C$8)&")" & CHAR(10) & ");", ");" ), " "&C13&" "&D13& _xlfn.IFS( E13="-", "", OR(D13="TIMESTAMP", D13="SMALLINT"), E13&IF(F13<>"-", ","&F13, ""), TRUE, "("&E13&IF(F13<>"-", ","&F13, "")&")" )& IF(G13<>"", " NOT NULL", "")& IF(H13<>"", ",", IF(B14<>"", ",", "") )& " -- "&B13 )} -> REPORT_CREATED_AT TIMESTAMP, -- レポート作成年月日
A15: =A14+1 -> 8 | B15: エラーメッセージ | C15: ERROR_MESSAGE | D15: VARCHAR | E15: 100 | F15: - | L15: {=IF(B14="", IF($L$6="PRIMARY_KEYS", ",PRIMARY KEY ("&_xlfn.TEXTJOIN(", ", TRUE, $C$8)&")" & CHAR(10) & ");", ");" ), " "&C14&" "&D14& _xlfn.IFS( E14="-", "", OR(D14="TIMESTAMP", D14="SMALLINT"), E14&IF(F14<>"-", ","&F14, ""), TRUE, "("&E14&IF(F14<>"-", ","&F14, "")&")" )& IF(G14<>"", " NOT NULL", "")& IF(H14<>"", ",", IF(B15<>"", ",", "") )& " -- "&B14 )} -> CREATE_STATUS VARCHAR(1) NOT NULL, -- 作成状態
A16: =A15+1 -> 9 | B16: ファイルパス | C16: FILE_PATH | D16: VARCHAR | E16: 255 | F16: - | L16: {=IF(B15="", IF($L$6="PRIMARY_KEYS", ",PRIMARY KEY ("&_xlfn.TEXTJOIN(", ", TRUE, $C$8)&")" & CHAR(10) & ");", ");" ), " "&C15&" "&D15& _xlfn.IFS( E15="-", "", OR(D15="TIMESTAMP", D15="SMALLINT"), E15&IF(F15<>"-", ","&F15, ""), TRUE, "("&E15&IF(F15<>"-", ","&F15, "")&")" )& IF(G15<>"", " NOT NULL", "")& IF(H15<>"", ",", IF(B16<>"", ",", "") )& " -- "&B15 )} -> ERROR_MESSAGE VARCHAR(100), -- エラーメッセージ
A17: =A16+1 -> 10 | B17: 作成者 | C17: CREATED_BY | D17: VARCHAR | E17: 50 | F17: - | G17: 〇 | L17: {=IF(B16="", IF($L$6="PRIMARY_KEYS", ",PRIMARY KEY ("&_xlfn.TEXTJOIN(", ", TRUE, $C$8)&")" & CHAR(10) & ");", ");" ), " "&C16&" "&D16& _xlfn.IFS( E16="-", "", OR(D16="TIMESTAMP", D16="SMALLINT"), E16&IF(F16<>"-", ","&F16, ""), TRUE, "("&E16&IF(F16<>"-", ","&F16, "")&")" )& IF(G16<>"", " NOT NULL", "")& IF(H16<>"", ",", IF(B17<>"", ",", "") )& " -- "&B16 )} -> FILE_PATH VARCHAR(255), -- ファイルパス
A18: =A17+1 -> 11 | B18: 作成日時 | C18: CREATED_AT | D18: TIMESTAMP | E18: - | F18: - | G18: 〇 | I18: レコード作成日時 | L18: {=IF(B17="", IF($L$6="PRIMARY_KEYS", ",PRIMARY KEY ("&_xlfn.TEXTJOIN(", ", TRUE, $C$8)&")" & CHAR(10) & ");", ");" ), " "&C17&" "&D17& _xlfn.IFS( E17="-", "", OR(D17="TIMESTAMP", D17="SMALLINT"), E17&IF(F17<>"-", ","&F17, ""), TRUE, "("&E17&IF(F17<>"-", ","&F17, "")&")" )& IF(G17<>"", " NOT NULL", "")& IF(H17<>"", ",", IF(B18<>"", ",", "") )& " -- "&B17 )} -> CREATED_BY VARCHAR(50) NOT NULL, -- 作成者
A19: =A18+1 -> 12 | B19: 更新者 | C19: UPDATED_BY | D19: VARCHAR | E19: 50 | F19: - | L19: {=IF(B18="", IF($L$6="PRIMARY_KEYS", ",PRIMARY KEY ("&_xlfn.TEXTJOIN(", ", TRUE, $C$8)&")" & CHAR(10) & ");", ");" ), " "&C18&" "&D18& _xlfn.IFS( E18="-", "", OR(D18="TIMESTAMP", D18="SMALLINT"), E18&IF(F18<>"-", ","&F18, ""), TRUE, "("&E18&IF(F18<>"-", ","&F18, "")&")" )& IF(G18<>"", " NOT NULL", "")& IF(H18<>"", ",", IF(B19<>"", ",", "") )& " -- "&B18 )} -> CREATED_AT TIMESTAMP NOT NULL, -- 作成日時
A20: =A19+1 -> 13 | B20: 更新日時 | C20: UPDATED_AT | D20: TIMESTAMP | E20: - | F20: - | I20: レコード更新日時 | L20: {=IF(B19="", IF($L$6="PRIMARY_KEYS", ",PRIMARY KEY ("&_xlfn.TEXTJOIN(", ", TRUE, $C$8)&")" & CHAR(10) & ");", ");" ), " "&C19&" "&D19& _xlfn.IFS( E19="-", "", OR(D19="TIMESTAMP", D19="SMALLINT"), E19&IF(F19<>"-", ","&F19, ""), TRUE, "("&E19&IF(F19<>"-", ","&F19, "")&")" )& IF(G19<>"", " NOT NULL", "")& IF(H19<>"", ",", IF(B20<>"", ",", "") )& " -- "&B19 )} -> UPDATED_BY VARCHAR(50), -- 更新者
L21: {=IF(B20="", IF($L$6="PRIMARY_KEYS", ",PRIMARY KEY ("&_xlfn.TEXTJOIN(", ", TRUE, $C$8)&")" & CHAR(10) & ");", ");" ), " "&C20&" "&D20& _xlfn.IFS( E20="-", "", OR(D20="TIMESTAMP", D20="SMALLINT"), E20&IF(F20<>"-", ","&F20, ""), TRUE, "("&E20&IF(F20<>"-", ","&F20, "")&")" )& IF(G20<>"", " NOT NULL", "")& IF(H20<>"", ",", IF(B21<>"", ",", "") )& " -- "&B20 )} -> UPDATED_AT TIMESTAMP -- 更新日時
L22: {=IF(B21="", IF($L$6="PRIMARY_KEYS", ",PRIMARY KEY ("&_xlfn.TEXTJOIN(", ", TRUE, $C$8)&")" & CHAR(10) & ");", ");" ), " "&C21&" "&D21& _xlfn.IFS( E21="-", "", OR(D21="TIMESTAMP", D21="SMALLINT"), E21&IF(F21<>"-", ","&F21, ""), TRUE, "("&E21&IF(F21<>"-", ","&F21, "")&")" )& IF(G21<>"", " NOT NULL", "")& IF(H21<>"", ",", IF(B22<>"", ",", "") )& " -- "&B21 )} -> ,PRIMARY KEY (SUPPLY_POINT_NUMBER) );
L25: ="COMMENT ON TABLE db_corp." & A5 & " IS '" & A3 & "';" -> COMMENT ON TABLE db_corp.T_POWER_REPORT_MNG_INFO IS '電力見える化レポート管理情報';
L26: ="COMMENT ON COLUMN db_corp." & $A$5&"."&C8&" IS '" &B8&"';" -> COMMENT ON COLUMN db_corp.T_POWER_REPORT_MNG_INFO.SUPPLY_POINT_NUMBER IS '供給地点特定番号(FK)';
L27: ="COMMENT ON COLUMN db_corp." & $A$5&"."&C9&" IS '" &B9&"';" -> COMMENT ON COLUMN db_corp.T_POWER_REPORT_MNG_INFO.TARGET_YEAR_MONTH IS '対象年月';
L28: ="COMMENT ON COLUMN db_corp." & $A$5&"."&C10&" IS '" &B10&"';" -> COMMENT ON COLUMN db_corp.T_POWER_REPORT_MNG_INFO.COMPANY_ID IS '企業ID';
L29: ="COMMENT ON COLUMN db_corp." & $A$5&"."&C11&" IS '" &B11&"';" -> COMMENT ON COLUMN db_corp.T_POWER_REPORT_MNG_INFO.SYOUSAPO_FLG IS '省エネサポートサービス加入フラグ';
L30: ="COMMENT ON COLUMN db_corp." & $A$5&"."&C12&" IS '" &B12&"';" -> COMMENT ON COLUMN db_corp.T_POWER_REPORT_MNG_INFO.FILE_NAME IS 'ファイル名';
L31: ="COMMENT ON COLUMN db_corp." & $A$5&"."&C13&" IS '" &B13&"';" -> COMMENT ON COLUMN db_corp.T_POWER_REPORT_MNG_INFO.REPORT_CREATED_AT IS 'レポート作成年月日';
L32: ="COMMENT ON COLUMN db_corp." & $A$5&"."&C14&" IS '" &B14&"';" -> COMMENT ON COLUMN db_corp.T_POWER_REPORT_MNG_INFO.CREATE_STATUS IS '作成状態';
L33: ="COMMENT ON COLUMN db_corp." & $A$5&"."&C15&" IS '" &B15&"';" -> COMMENT ON COLUMN db_corp.T_POWER_REPORT_MNG_INFO.ERROR_MESSAGE IS 'エラーメッセージ';
L34: ="COMMENT ON COLUMN db_corp." & $A$5&"."&C16&" IS '" &B16&"';" -> COMMENT ON COLUMN db_corp.T_POWER_REPORT_MNG_INFO.FILE_PATH IS 'ファイルパス';
L35: ="COMMENT ON COLUMN db_corp." & $A$5&"."&C17&" IS '" &B17&"';" -> COMMENT ON COLUMN db_corp.T_POWER_REPORT_MNG_INFO.CREATED_BY IS '作成者';
L36: ="COMMENT ON COLUMN db_corp." & $A$5&"."&C18&" IS '" &B18&"';" -> COMMENT ON COLUMN db_corp.T_POWER_REPORT_MNG_INFO.CREATED_AT IS '作成日時';
L37: ="COMMENT ON COLUMN db_corp." & $A$5&"."&C19&" IS '" &B19&"';" -> COMMENT ON COLUMN db_corp.T_POWER_REPORT_MNG_INFO.UPDATED_BY IS '更新者';
... L40: ="COMMENT ON COLUMN db_corp." & $A$5&"."&C22&" IS '" &B22&"';" -> COMMENT ON COLUMN db_corp.T_POWER_REPORT_MNG_INFO. IS '';

Sheet EPデータ参照基盤契約電力
D1: =修正履歴!E7 -> 2026/12/21
A2: テーブル名（日本語） | D2: システム名 | I2: 作成者 | J2: 承認者 | K2: 作成日
A3: EPデータ参照基盤契約電力 | D3: CNレポート作成アプリ「LecMoc」
A4: テーブル名（英語） | D4: スキーマ | I4: 更新者 | J4: 承認者 | K4: 更新日
A5: T_EP_CONTRACTED_POWER | D5: DB_CORP
A6: EPデータ参照基盤から受領するテーブルのため、項目名および型桁はEPデータ参照基盤に合わせ定義する ※青字のものはそのまま登録する項目 | L6: PRIMARY_KEYS
A7: No | B7: 論理名 | C7: 物理名 | D7: 型 | E7: 長さ | F7: 精度 | G7: 必須 | H7: 主キー（PK） | I7: 備考 | L7: ="drop TABLE IF EXISTS db_corp."&A5&" CASCADE;" -> drop TABLE IF EXISTS db_corp.T_EP_CONTRACTED_POWER CASCADE;
A8: 1 | B8: 供給(受電)地点特定番号 | C8: QSQB_DCIS2_SPL_PT_SPC_NO | D8: VARCHAR | E8: 22 | F8: - | G8: 〇 | H8: 1 | L8: ="CREATE TABLE IF NOT EXISTS db_corp."&A5&" (" -> CREATE TABLE IF NOT EXISTS db_corp.T_EP_CONTRACTED_POWER (
A9: =A8+1 -> 2 | B9: 高圧契約電力(kW) | C9: QSQB_DCIS2_HVPW_CTRT | D9: INTEGER | E9: 10 | F9: 0 | G9: 〇 | L9: {=IF(B8="", IF($L$6="PRIMARY_KEYS", ",PRIMARY KEY ("&_xlfn.TEXTJOIN(", ", TRUE, $C$8)&")" & CHAR(10) & ");", ");" ), " "&C8&" "&D8& _xlfn.IFS( E8="-", "", OR(D8="TIMESTAMP", D8="SMALLINT"), E8&IF(F8<>"-", ","&F8, ""), TRUE, "("&E8&IF(F8<>"-", ","&F8, "")&")" )& IF(G8<>"", " NOT NULL", "")& IF(H8<>"", ",", IF(B9<>"", ",", "") )& " -- "&B8 )} -> QSQB_DCIS2_SPL_PT_SPC_NO VARCHAR(22) NOT NULL, -- 供給(受電)地点特定番号
A10: =A9+1 -> 3 | B10: 作成者 | C10: CREATED_BY | D10: VARCHAR | E10: 50 | F10: - | G10: 〇 | L10: {=IF(B9="", IF($L$6="PRIMARY_KEYS", ",PRIMARY KEY ("&_xlfn.TEXTJOIN(", ", TRUE, $C$8)&")" & CHAR(10) & ");", ");" ), " "&C9&" "&D9& _xlfn.IFS( E9="-", "", OR(D9="TIMESTAMP", D9="SMALLINT"), E9&IF(F9<>"-", ","&F9, ""), TRUE, "("&E9&IF(F9<>"-", ","&F9, "")&")" )& IF(G9<>"", " NOT NULL", "")& IF(H9<>"", ",", IF(B10<>"", ",", "") )& " -- "&B9 )} -> QSQB_DCIS2_HVPW_CTRT INTEGER(10,0) NOT NULL, -- 高圧契約電力(kW)
A11: =A10+1 -> 4 | B11: 作成日時 | C11: CREATED_AT | D11: TIMESTAMP | E11: - | F11: - | G11: 〇 | I11: レコード作成日時 | L11: {=IF(B10="", IF($L$6="PRIMARY_KEYS", ",PRIMARY KEY ("&_xlfn.TEXTJOIN(", ", TRUE, $C$8)&")" & CHAR(10) & ");", ");" ), " "&C10&" "&D10& _xlfn.IFS( E10="-", "", OR(D10="TIMESTAMP", D10="SMALLINT"), E10&IF(F10<>"-", ","&F10, ""), TRUE, "("&E10&IF(F10<>"-", ","&F10, "")&")" )& IF(G10<>"", " NOT NULL", "")& IF(H10<>"", ",", IF(B11<>"", ",", "") )& " -- "&B10 )} -> CREATED_BY VARCHAR(50) NOT NULL, -- 作成者
A12: =A11+1 -> 5 | B12: 更新者 | C12: UPDATED_BY | D12: VARCHAR | E12: 50 | F12: - | L12: {=IF(B11="", IF($L$6="PRIMARY_KEYS", ",PRIMARY KEY ("&_xlfn.TEXTJOIN(", ", TRUE, $C$8)&")" & CHAR(10) & ");", ");" ), " "&C11&" "&D11& _xlfn.IFS( E11="-", "", OR(D11="TIMESTAMP", D11="SMALLINT"), E11&IF(F11<>"-", ","&F11, ""), TRUE, "("&E11&IF(F11<>"-", ","&F11, "")&")" )& IF(G11<>"", " NOT NULL", "")& IF(H11<>"", ",", IF(B12<>"", ",", "") )& " -- "&B11 )} -> CREATED_AT TIMESTAMP NOT NULL, -- 作成日時
A13: =A12+1 -> 6 | B13: 更新日時 | C13: UPDATED_AT | D13: TIMESTAMP | E13: - | F13: - | I13: レコード更新日時 | L13: {=IF(B12="", IF($L$6="PRIMARY_KEYS", ",PRIMARY KEY ("&_xlfn.TEXTJOIN(", ", TRUE, $C$8)&")" & CHAR(10) & ");", ");" ), " "&C12&" "&D12& _xlfn.IFS( E12="-", "", OR(D12="TIMESTAMP", D12="SMALLINT"), E12&IF(F12<>"-", ","&F12, ""), TRUE, "("&E12&IF(F12<>"-", ","&F12, "")&")" )& IF(G12<>"", " NOT NULL", "")& IF(H12<>"", ",", IF(B13<>"", ",", "") )& " -- "&B12 )} -> UPDATED_BY VARCHAR(50), -- 更新者
L14: {=IF(B13="", IF($L$6="PRIMARY_KEYS", ",PRIMARY KEY ("&_xlfn.TEXTJOIN(", ", TRUE, $C$8)&")" & CHAR(10) & ");", ");" ), " "&C13&" "&D13& _xlfn.IFS( E13="-", "", OR(D13="TIMESTAMP", D13="SMALLINT"), E13&IF(F13<>"-", ","&F13, ""), TRUE, "("&E13&IF(F13<>"-", ","&F13, "")&")" )& IF(G13<>"", " NOT NULL", "")& IF(H13<>"", ",", IF(B14<>"", ",", "") )& " -- "&B13 )} -> UPDATED_AT TIMESTAMP -- 更新日時
L15: {=IF(B14="", IF($L$6="PRIMARY_KEYS", ",PRIMARY KEY ("&_xlfn.TEXTJOIN(", ", TRUE, $C$8)&")" & CHAR(10) & ");", ");" ), " "&C14&" "&D14& _xlfn.IFS( E14="-", "", OR(D14="TIMESTAMP", D14="SMALLINT"), E14&IF(F14<>"-", ","&F14, ""), TRUE, "("&E14&IF(F14<>"-", ","&F14, "")&")" )& IF(G14<>"", " NOT NULL", "")& IF(H14<>"", ",", IF(B15<>"", ",", "") )& " -- "&B14 )} -> ,PRIMARY KEY (QSQB_DCIS2_SPL_PT_SPC_NO) );
L17: ="COMMENT ON TABLE db_corp." & A5 & " IS '" & A3 & "';" -> COMMENT ON TABLE db_corp.T_EP_CONTRACTED_POWER IS 'EPデータ参照基盤契約電力';
L18: ="COMMENT ON COLUMN db_corp." & $A$5&"."&C8&" IS '" &B8&"';" -> COMMENT ON COLUMN db_corp.T_EP_CONTRACTED_POWER.QSQB_DCIS2_SPL_PT_SPC_NO IS '供給(受電)地点特定番号';
L19: ="COMMENT ON COLUMN db_corp." & $A$5&"."&C9&" IS '" &B9&"';" -> COMMENT ON COLUMN db_corp.T_EP_CONTRACTED_POWER.QSQB_DCIS2_HVPW_CTRT IS '高圧契約電力(kW)';
L20: ="COMMENT ON COLUMN db_corp." & $A$5&"."&C10&" IS '" &B10&"';" -> COMMENT ON COLUMN db_corp.T_EP_CONTRACTED_POWER.CREATED_BY IS '作成者';
L21: ="COMMENT ON COLUMN db_corp." & $A$5&"."&C11&" IS '" &B11&"';" -> COMMENT ON COLUMN db_corp.T_EP_CONTRACTED_POWER.CREATED_AT IS '作成日時';
L22: ="COMMENT ON COLUMN db_corp." & $A$5&"."&C12&" IS '" &B12&"';" -> COMMENT ON COLUMN db_corp.T_EP_CONTRACTED_POWER.UPDATED_BY IS '更新者';
L23: ="COMMENT ON COLUMN db_corp." & $A$5&"."&C13&" IS '" &B13&"';" -> COMMENT ON COLUMN db_corp.T_EP_CONTRACTED_POWER.UPDATED_AT IS '更新日時';

Sheet EPデータ参照基盤30分値
D1: =修正履歴!E7 -> 2026/12/21
A2: テーブル名（日本語） | D2: システム名 | I2: 作成者 | J2: 承認者 | K2: 作成日
A3: EPデータ参照基盤30分値 | D3: CNレポート作成アプリ「LecMoc」
A4: テーブル名（英語） | D4: スキーマ | I4: 更新者 | J4: 承認者 | K4: 更新日
A5: T_EP_ELECTRICITY_DATA_30MIN | D5: DB_CORP
A6: EPデータ参照基盤から受領するテーブルのため、項目名および型桁はEPデータ参照基盤に合わせ定義する ※青字のものはそのまま登録する項目 | L6: PRIMARY_KEYS
A7: No | B7: 論理名 | C7: 物理名 | D7: 型 | E7: 長さ | F7: 精度 | G7: 必須 | H7: 主キー（PK） | I7: 備考 | L7: ="drop TABLE IF EXISTS db_corp."&A5&" CASCADE;" -> drop TABLE IF EXISTS db_corp.T_EP_ELECTRICITY_DATA_30MIN CASCADE;
A8: 1 | B8: 供給地点特定番号(FK) | C8: T01_KYO_CTN_TOK_NO | D8: VARCHAR | E8: 22 | F8: - | G8: 〇 | H8: 1 | L8: ="CREATE TABLE IF NOT EXISTS db_corp."&A5&" (" -> CREATE TABLE IF NOT EXISTS db_corp.T_EP_ELECTRICITY_DATA_30MIN (
A9: =A8+1 -> 2 | B9: 取得年月日 | C9: T01_GET_YMD | D9: VARCHAR | E9: 8 | F9: - | G9: 〇 | H9: 2 | L9: {=IF(B8="", IF($L$6="PRIMARY_KEYS", ",PRIMARY KEY ("&_xlfn.TEXTJOIN(", ", TRUE, $C$8)&")" & CHAR(10) & ");", ");" ), " "&C8&" "&D8& _xlfn.IFS( E8="-", "", OR(D8="TIMESTAMP", D8="SMALLINT"), E8&IF(F8<>"-", ","&F8, ""), TRUE, "("&E8&IF(F8<>"-", ","&F8, "")&")" )& IF(G8<>"", " NOT NULL", "")& IF(H8<>"", ",", IF(B9<>"", ",", "") )& " -- "&B8 )} -> T01_KYO_CTN_TOK_NO VARCHAR(22) NOT NULL, -- 供給地点特定番号(FK)
A10: =A9+1 -> 3 | B10: 欠測時間帯件数 | C10: T01_KSKJ_KSU | D10: VARCHAR | E10: 2 | F10: - | G10: 〇 | L10: {=IF(B9="", IF($L$6="PRIMARY_KEYS", ",PRIMARY KEY ("&_xlfn.TEXTJOIN(", ", TRUE, $C$8)&")" & CHAR(10) & ");", ");" ), " "&C9&" "&D9& _xlfn.IFS( E9="-", "", OR(D9="TIMESTAMP", D9="SMALLINT"), E9&IF(F9<>"-", ","&F9, ""), TRUE, "("&E9&IF(F9<>"-", ","&F9, "")&")" )& IF(G9<>"", " NOT NULL", "")& IF(H9<>"", ",", IF(B10<>"", ",", "") )& " -- "&B9 )} -> T01_GET_YMD VARCHAR(8) NOT NULL, -- 取得年月日
A11: =A10+1 -> 4 | B11: 不正値時間帯件数 | C11: T01_FSIJ_KSU | D11: VARCHAR | E11: 2 | F11: - | G11: 〇 | L11: {=IF(B10="", IF($L$6="PRIMARY_KEYS", ",PRIMARY KEY ("&_xlfn.TEXTJOIN(", ", TRUE, $C$8)&")" & CHAR(10) & ");", ");" ), " "&C10&" "&D10& _xlfn.IFS( E10="-", "", OR(D10="TIMESTAMP", D10="SMALLINT"), E10&IF(F10<>"-", ","&F10, ""), TRUE, "("&E10&IF(F10<>"-", ","&F10, "")&")" )& IF(G10<>"", " NOT NULL", "")& IF(H10<>"", ",", IF(B11<>"", ",", "") )& " -- "&B10 )} -> T01_KSKJ_KSU VARCHAR(2) NOT NULL, -- 欠測時間帯件数
A12: =A11+1 -> 5 | B12: 30分使用電力量（1） | C12: T01_30T_SYR01 | D12: VARCHAR | E12: 9 | F12: - | G12: 〇 | L12: {=IF(B11="", IF($L$6="PRIMARY_KEYS", ",PRIMARY KEY ("&_xlfn.TEXTJOIN(", ", TRUE, $C$8)&")" & CHAR(10) & ");", ");" ), " "&C11&" "&D11& _xlfn.IFS( E11="-", "", OR(D11="TIMESTAMP", D11="SMALLINT"), E11&IF(F11<>"-", ","&F11, ""), TRUE, "("&E11&IF(F11<>"-", ","&F11, "")&")" )& IF(G11<>"", " NOT NULL", "")& IF(H11<>"", ",", IF(B12<>"", ",", "") )& " -- "&B11 )} -> T01_FSIJ_KSU VARCHAR(2) NOT NULL, -- 不正値時間帯件数
A13: =A12+1 -> 6 | B13: 30分使用電力量（2） | C13: T01_30T_SYR02 | D13: VARCHAR | E13: 9 | F13: - | G13: 〇 | L13: {=IF(B12="", IF($L$6="PRIMARY_KEYS", ",PRIMARY KEY ("&_xlfn.TEXTJOIN(", ", TRUE, $C$8)&")" & CHAR(10) & ");", ");" ), " "&C12&" "&D12& _xlfn.IFS( E12="-", "", OR(D12="TIMESTAMP", D12="SMALLINT"), E12&IF(F12<>"-", ","&F12, ""), TRUE, "("&E12&IF(F12<>"-", ","&F12, "")&")" )& IF(G12<>"", " NOT NULL", "")& IF(H12<>"", ",", IF(B13<>"", ",", "") )& " -- "&B12 )} -> T01_30T_SYR01 VARCHAR(9) NOT NULL, -- 30分使用電力量（1）
A14: =A13+1 -> 7 | B14: 30分使用電力量（3） | C14: T01_30T_SYR03 | D14: VARCHAR | E14: 9 | F14: - | G14: 〇 | L14: {=IF(B13="", IF($L$6="PRIMARY_KEYS", ",PRIMARY KEY ("&_xlfn.TEXTJOIN(", ", TRUE, $C$8)&")" & CHAR(10) & ");", ");" ), " "&C13&" "&D13& _xlfn.IFS( E13="-", "", OR(D13="TIMESTAMP", D13="SMALLINT"), E13&IF(F13<>"-", ","&F13, ""), TRUE, "("&E13&IF(F13<>"-", ","&F13, "")&")" )& IF(G13<>"", " NOT NULL", "")& IF(H13<>"", ",", IF(B14<>"", ",", "") )& " -- "&B13 )} -> T01_30T_SYR02 VARCHAR(9) NOT NULL, -- 30分使用電力量（2）
A15: =A14+1 -> 8 | B15: 30分使用電力量（4） | C15: T01_30T_SYR04 | D15: VARCHAR | E15: 9 | F15: - | G15: 〇 | L15: {=IF(B14="", IF($L$6="PRIMARY_KEYS", ",PRIMARY KEY ("&_xlfn.TEXTJOIN(", ", TRUE, $C$8)&")" & CHAR(10) & ");", ");" ), " "&C14&" "&D14& _xlfn.IFS( E14="-", "", OR(D14="TIMESTAMP", D14="SMALLINT"), E14&IF(F14<>"-", ","&F14, ""), TRUE, "("&E14&IF(F14<>"-", ","&F14, "")&")" )& IF(G14<>"", " NOT NULL", "")& IF(H14<>"", ",", IF(B15<>"", ",", "") )& " -- "&B14 )} -> T01_30T_SYR03 VARCHAR(9) NOT NULL, -- 30分使用電力量（3）
A16: =A15+1 -> 9 | B16: 30分使用電力量（5） | C16: T01_30T_SYR05 | D16: VARCHAR | E16: 9 | F16: - | G16: 〇 | L16: {=IF(B15="", IF($L$6="PRIMARY_KEYS", ",PRIMARY KEY ("&_xlfn.TEXTJOIN(", ", TRUE, $C$8)&")" & CHAR(10) & ");", ");" ), " "&C15&" "&D15& _xlfn.IFS( E15="-", "", OR(D15="TIMESTAMP", D15="SMALLINT"), E15&IF(F15<>"-", ","&F15, ""), TRUE, "("&E15&IF(F15<>"-", ","&F15, "")&")" )& IF(G15<>"", " NOT NULL", "")& IF(H15<>"", ",", IF(B16<>"", ",", "") )& " -- "&B15 )} -> T01_30T_SYR04 VARCHAR(9) NOT NULL, -- 30分使用電力量（4）
A17: =A16+1 -> 10 | B17: 30分使用電力量（6） | C17: T01_30T_SYR06 | D17: VARCHAR | E17: 9 | F17: - | G17: 〇 | L17: {=IF(B16="", IF($L$6="PRIMARY_KEYS", ",PRIMARY KEY ("&_xlfn.TEXTJOIN(", ", TRUE, $C$8)&")" & CHAR(10) & ");", ");" ), " "&C16&" "&D16& _xlfn.IFS( E16="-", "", OR(D16="TIMESTAMP", D16="SMALLINT"), E16&IF(F16<>"-", ","&F16, ""), TRUE, "("&E16&IF(F16<>"-", ","&F16, "")&")" )& IF(G16<>"", " NOT NULL", "")& IF(H16<>"", ",", IF(B17<>"", ",", "") )& " -- "&B16 )} -> T01_30T_SYR05 VARCHAR(9) NOT NULL, -- 30分使用電力量（5）
A18: =A17+1 -> 11 | B18: 30分使用電力量（7） | C18: T01_30T_SYR07 | D18: VARCHAR | E18: 9 | F18: - | G18: 〇 | L18: {=IF(B17="", IF($L$6="PRIMARY_KEYS", ",PRIMARY KEY ("&_xlfn.TEXTJOIN(", ", TRUE, $C$8)&")" & CHAR(10) & ");", ");" ), " "&C17&" "&D17& _xlfn.IFS( E17="-", "", OR(D17="TIMESTAMP", D17="SMALLINT"), E17&IF(F17<>"-", ","&F17, ""), TRUE, "("&E17&IF(F17<>"-", ","&F17, "")&")" )& IF(G17<>"", " NOT NULL", "")& IF(H17<>"", ",", IF(B18<>"", ",", "") )& " -- "&B17 )} -> T01_30T_SYR06 VARCHAR(9) NOT NULL, -- 30分使用電力量（6）
A19: =A18+1 -> 12 | B19: 30分使用電力量（8） | C19: T01_30T_SYR08 | D19: VARCHAR | E19: 9 | F19: - | G19: 〇 | L19: {=IF(B18="", IF($L$6="PRIMARY_KEYS", ",PRIMARY KEY ("&_xlfn.TEXTJOIN(", ", TRUE, $C$8)&")" & CHAR(10) & ");", ");" ), " "&C18&" "&D18& _xlfn.IFS( E18="-", "", OR(D18="TIMESTAMP", D18="SMALLINT"), E18&IF(F18<>"-", ","&F18, ""), TRUE, "("&E18&IF(F18<>"-", ","&F18, "")&")" )& IF(G18<>"", " NOT NULL", "")& IF(H18<>"", ",", IF(B19<>"", ",", "") )& " -- "&B18 )} -> T01_30T_SYR07 VARCHAR(9) NOT NULL, -- 30分使用電力量（7）
A20: =A19+1 -> 13 | B20: 30分使用電力量（9） | C20: T01_30T_SYR09 | D20: VARCHAR | E20: 9 | F20: - | G20: 〇 | L20: {=IF(B19="", IF($L$6="PRIMARY_KEYS", ",PRIMARY KEY ("&_xlfn.TEXTJOIN(", ", TRUE, $C$8)&")" & CHAR(10) & ");", ");" ), " "&C19&" "&D19& _xlfn.IFS( E19="-", "", OR(D19="TIMESTAMP", D19="SMALLINT"), E19&IF(F19<>"-", ","&F19, ""), TRUE, "("&E19&IF(F19<>"-", ","&F19, "")&")" )& IF(G19<>"", " NOT NULL", "")& IF(H19<>"", ",", IF(B20<>"", ",", "") )& " -- "&B19 )} -> T01_30T_SYR08 VARCHAR(9) NOT NULL, -- 30分使用電力量（8）
A21: =A20+1 -> 14 | B21: 30分使用電力量（10） | C21: T01_30T_SYR10 | D21: VARCHAR | E21: 9 | F21: - | G21: 〇 | L21: {=IF(B20="", IF($L$6="PRIMARY_KEYS", ",PRIMARY KEY ("&_xlfn.TEXTJOIN(", ", TRUE, $C$8)&")" & CHAR(10) & ");", ");" ), " "&C20&" "&D20& _xlfn.IFS( E20="-", "", OR(D20="TIMESTAMP", D20="SMALLINT"), E20&IF(F20<>"-", ","&F20, ""), TRUE, "("&E20&IF(F20<>"-", ","&F20, "")&")" )& IF(G20<>"", " NOT NULL", "")& IF(H20<>"", ",", IF(B21<>"", ",", "") )& " -- "&B20 )} -> T01_30T_SYR09 VARCHAR(9) NOT NULL, -- 30分使用電力量（9）
... A60: =A59+1 -> 53 | B60: 作成者 | C60: CREATED_BY | D60: VARCHAR | E60: 50 | F60: - | G60: 〇 | L60: {=IF(B59="", IF($L$6="PRIMARY_KEYS", ",PRIMARY KEY ("&_xlfn.TEXTJOIN(", ", TRUE, $C$8)&")" & CHAR(10) & ");", ");" ), " "&C59&" "&D59& _xlfn.IFS( E59="-", "", OR(D59="TIMESTAMP", D59="SMALLINT"), E59&IF(F59<>"-", ","&F59, ""), TRUE, "("&E59&IF(F59<>"-", ","&F59, "")&")" )& IF(G59<>"", " NOT NULL", "")& IF(H59<>"", ",", IF(B60<>"", ",", "") )& " -- "&B59 )} -> T01_30T_SYR48 VARCHAR(9) NOT NULL, -- 30分使用電力量（48）
A61: =A60+1 -> 54 | B61: 作成日時 | C61: CREATED_AT | D61: TIMESTAMP | E61: - | F61: - | G61: 〇 | I61: レコード作成日時 | L61: {=IF(B60="", IF($L$6="PRIMARY_KEYS", ",PRIMARY KEY ("&_xlfn.TEXTJOIN(", ", TRUE, $C$8)&")" & CHAR(10) & ");", ");" ), " "&C60&" "&D60& _xlfn.IFS( E60="-", "", OR(D60="TIMESTAMP", D60="SMALLINT"), E60&IF(F60<>"-", ","&F60, ""), TRUE, "("&E60&IF(F60<>"-", ","&F60, "")&")" )& IF(G60<>"", " NOT NULL", "")& IF(H60<>"", ",", IF(B61<>"", ",", "") )& " -- "&B60 )} -> CREATED_BY VARCHAR(50) NOT NULL, -- 作成者
A62: =A61+1 -> 55 | B62: 更新者 | C62: UPDATED_BY | D62: VARCHAR | E62: 50 | F62: - | L62: {=IF(B61="", IF($L$6="PRIMARY_KEYS", ",PRIMARY KEY ("&_xlfn.TEXTJOIN(", ", TRUE, $C$8)&")" & CHAR(10) & ");", ");" ), " "&C61&" "&D61& _xlfn.IFS( E61="-", "", OR(D61="TIMESTAMP", D61="SMALLINT"), E61&IF(F61<>"-", ","&F61, ""), TRUE, "("&E61&IF(F61<>"-", ","&F61, "")&")" )& IF(G61<>"", " NOT NULL", "")& IF(H61<>"", ",", IF(B62<>"", ",", "") )& " -- "&B61 )} -> CREATED_AT TIMESTAMP NOT NULL, -- 作成日時
A63: =A62+1 -> 56 | B63: 更新日時 | C63: UPDATED_AT | D63: TIMESTAMP | E63: - | F63: - | I63: レコード更新日時 | L63: {=IF(B62="", IF($L$6="PRIMARY_KEYS", ",PRIMARY KEY ("&_xlfn.TEXTJOIN(", ", TRUE, $C$8)&")" & CHAR(10) & ");", ");" ), " "&C62&" "&D62& _xlfn.IFS( E62="-", "", OR(D62="TIMESTAMP", D62="SMALLINT"), E62&IF(F62<>"-", ","&F62, ""), TRUE, "("&E62&IF(F62<>"-", ","&F62, "")&")" )& IF(G62<>"", " NOT NULL", "")& IF(H62<>"", ",", IF(B63<>"", ",", "") )& " -- "&B62 )} -> UPDATED_BY VARCHAR(50), -- 更新者
L64: {=IF(B63="", IF($L$6="PRIMARY_KEYS", ",PRIMARY KEY ("&_xlfn.TEXTJOIN(", ", TRUE, $C$8)&")" & CHAR(10) & ");", ");" ), " "&C63&" "&D63& _xlfn.IFS( E63="-", "", OR(D63="TIMESTAMP", D63="SMALLINT"), E63&IF(F63<>"-", ","&F63, ""), TRUE, "("&E63&IF(F63<>"-", ","&F63, "")&")" )& IF(G63<>"", " NOT NULL", "")& IF(H63<>"", ",", IF(B64<>"", ",", "") )& " -- "&B63 )} -> UPDATED_AT TIMESTAMP -- 更新日時
L65: {=IF(B64="", IF($L$6="PRIMARY_KEYS", ",PRIMARY KEY ("&_xlfn.TEXTJOIN(", ", TRUE, $C$8, $C$9)&")" & CHAR(10) & ");", ");" ), " "&C64&" "&D64& _xlfn.IFS( E64="-", "", OR(D64="TIMESTAMP", D64="SMALLINT"), E64&IF(F64<>"-", ","&F64, ""), TRUE, "("&E64&IF(F64<>"-", ","&F64, "")&")" )& IF(G64<>"", " NOT NULL", "")& IF(H64<>"", ",", IF(B65<>"", ",", "") )& " -- "&B64 )} -> ,PRIMARY KEY (T01_KYO_CTN_TOK_NO, T01_GET_YMD) );
L67: ="COMMENT ON TABLE db_corp." & $A$5 & " IS '" & $A$3 & "';" -> COMMENT ON TABLE db_corp.T_EP_ELECTRICITY_DATA_30MIN IS 'EPデータ参照基盤30分値';
L68: ="COMMENT ON COLUMN db_corp." & $A$5&"."&C8&" IS '" &B8&"';" -> COMMENT ON COLUMN db_corp.T_EP_ELECTRICITY_DATA_30MIN.T01_KYO_CTN_TOK_NO IS '供給地点特定番号(FK)';
L69: ="COMMENT ON COLUMN db_corp." & $A$5&"."&C9&" IS '" &B9&"';" -> COMMENT ON COLUMN db_corp.T_EP_ELECTRICITY_DATA_30MIN.T01_GET_YMD IS '取得年月日';
L70: ="COMMENT ON COLUMN db_corp." & $A$5&"."&C10&" IS '" &B10&"';" -> COMMENT ON COLUMN db_corp.T_EP_ELECTRICITY_DATA_30MIN.T01_KSKJ_KSU IS '欠測時間帯件数';
L71: ="COMMENT ON COLUMN db_corp." & $A$5&"."&C11&" IS '" &B11&"';" -> COMMENT ON COLUMN db_corp.T_EP_ELECTRICITY_DATA_30MIN.T01_FSIJ_KSU IS '不正値時間帯件数';
L72: ="COMMENT ON COLUMN db_corp." & $A$5&"."&C12&" IS '" &B12&"';" -> COMMENT ON COLUMN db_corp.T_EP_ELECTRICITY_DATA_30MIN.T01_30T_SYR01 IS '30分使用電力量（1）';
L73: ="COMMENT ON COLUMN db_corp." & $A$5&"."&C13&" IS '" &B13&"';" -> COMMENT ON COLUMN db_corp.T_EP_ELECTRICITY_DATA_30MIN.T01_30T_SYR02 IS '30分使用電力量（2）';
L74: ="COMMENT ON COLUMN db_corp." & $A$5&"."&C14&" IS '" &B14&"';" -> COMMENT ON COLUMN db_corp.T_EP_ELECTRICITY_DATA_30MIN.T01_30T_SYR03 IS '30分使用電力量（3）';
L75: ="COMMENT ON COLUMN db_corp." & $A$5&"."&C15&" IS '" &B15&"';" -> COMMENT ON COLUMN db_corp.T_EP_ELECTRICITY_DATA_30MIN.T01_30T_SYR04 IS '30分使用電力量（4）';
L76: ="COMMENT ON COLUMN db_corp." & $A$5&"."&C16&" IS '" &B16&"';" -> COMMENT ON COLUMN db_corp.T_EP_ELECTRICITY_DATA_30MIN.T01_30T_SYR05 IS '30分使用電力量（5）';
L77: ="COMMENT ON COLUMN db_corp." & $A$5&"."&C17&" IS '" &B17&"';" -> COMMENT ON COLUMN db_corp.T_EP_ELECTRICITY_DATA_30MIN.T01_30T_SYR06 IS '30分使用電力量（6）';
L78: ="COMMENT ON COLUMN db_corp." & $A$5&"."&C18&" IS '" &B18&"';" -> COMMENT ON COLUMN db_corp.T_EP_ELECTRICITY_DATA_30MIN.T01_30T_SYR07 IS '30分使用電力量（7）';
L79: ="COMMENT ON COLUMN db_corp." & $A$5&"."&C19&" IS '" &B19&"';" -> COMMENT ON COLUMN db_corp.T_EP_ELECTRICITY_DATA_30MIN.T01_30T_SYR08 IS '30分使用電力量（8）';
...

Sheet 30分値取込管理
D1: =修正履歴!E7 -> 2026/12/21
A2: テーブル名（日本語） | D2: システム名 | I2: 作成者 | J2: 承認者 | K2: 作成日
A3: 30分値取込管理 | D3: CNレポート作成アプリ「LecMoc」
A4: テーブル名（英語） | D4: スキーマ | I4: 更新者 | J4: 承認者 | K4: 更新日
A5: T_30MIN_IMPORT_MNG | D5: DB_CORP
L6: PRIMARY_KEYS
A7: No | B7: 論理名 | C7: 物理名 | D7: 型 | E7: 長さ | F7: 精度 | G7: 必須 | H7: 主キー（PK） | I7: 備考 | L7: ="drop TABLE IF EXISTS db_corp."&A5&" CASCADE;" -> drop TABLE IF EXISTS db_corp.T_30MIN_IMPORT_MNG CASCADE;
A8: 1 | B8: 供給地点特定番号(FK) | C8: SUPPLY_POINT_NUMBER | D8: VARCHAR | E8: 22 | F8: - | G8: 〇 | H8: 1 | L8: ="CREATE TABLE IF NOT EXISTS db_corp."&A5&" (" -> CREATE TABLE IF NOT EXISTS db_corp.T_30MIN_IMPORT_MNG (
A9: =A8+1 -> 2 | B9: 対象年月 | C9: TARGET_YEAR_MONTH | D9: VARCHAR | E9: 6 | F9: - | G9: 〇 | H9: 2 | I9: レポート作成対象年月 | L9: {=IF(B8="", IF($L$6="PRIMARY_KEYS", ",PRIMARY KEY ("&_xlfn.TEXTJOIN(", ", TRUE, $C$8)&")" & CHAR(10) & ");", ");" ), " "&C8&" "&D8& _xlfn.IFS( E8="-", "", OR(D8="TIMESTAMP", D8="SMALLINT"), E8&IF(F8<>"-", ","&F8, ""), TRUE, "("&E8&IF(F8<>"-", ","&F8, "")&")" )& IF(G8<>"", " NOT NULL", "")& IF(H8<>"", ",", IF(B9<>"", ",", "") )& " -- "&B8 )} -> SUPPLY_POINT_NUMBER VARCHAR(22) NOT NULL, -- 供給地点特定番号(FK)
A10: =A9+1 -> 3 | B10: 作成状態 | C10: CREATE_STATUS | D10: VARCHAR | E10: 1 | F10: - | G10: 〇 | I10: 1:作成依頼 2:作成中 3:完了4:完了（警告）5:エラー | L10: {=IF(B9="", IF($L$6="PRIMARY_KEYS", ",PRIMARY KEY ("&_xlfn.TEXTJOIN(", ", TRUE, $C$8)&")" & CHAR(10) & ");", ");" ), " "&C9&" "&D9& _xlfn.IFS( E9="-", "", OR(D9="TIMESTAMP", D9="SMALLINT"), E9&IF(F9<>"-", ","&F9, ""), TRUE, "("&E9&IF(F9<>"-", ","&F9, "")&")" )& IF(G9<>"", " NOT NULL", "")& IF(H9<>"", ",", IF(B10<>"", ",", "") )& " -- "&B9 )} -> TARGET_YEAR_MONTH VARCHAR(6) NOT NULL, -- 対象年月
A11: =A10+1 -> 4 | B11: エラーメッセージ | C11: ERROR_MESSAGE | D11: VARCHAR | E11: 100 | F11: - | L11: {=IF(B10="", IF($L$6="PRIMARY_KEYS", ",PRIMARY KEY ("&_xlfn.TEXTJOIN(", ", TRUE, $C$8)&")" & CHAR(10) & ");", ");" ), " "&C10&" "&D10& _xlfn.IFS( E10="-", "", OR(D10="TIMESTAMP", D10="SMALLINT"), E10&IF(F10<>"-", ","&F10, ""), TRUE, "("&E10&IF(F10<>"-", ","&F10, "")&")" )& IF(G10<>"", " NOT NULL", "")& IF(H10<>"", ",", IF(B11<>"", ",", "") )& " -- "&B10 )} -> CREATE_STATUS VARCHAR(1) NOT NULL, -- 作成状態
A12: =A11+1 -> 5 | B12: 紐付けエラーメッセージ | C12: LINKED_ERROR_MESSAGE | D12: VARCHAR | E12: 100 | F12: - | L12: {=IF(B11="", IF($L$6="PRIMARY_KEYS", ",PRIMARY KEY ("&_xlfn.TEXTJOIN(", ", TRUE, $C$8)&")" & CHAR(10) & ");", ");" ), " "&C11&" "&D11& _xlfn.IFS( E11="-", "", OR(D11="TIMESTAMP", D11="SMALLINT"), E11&IF(F11<>"-", ","&F11, ""), TRUE, "("&E11&IF(F11<>"-", ","&F11, "")&")" )& IF(G11<>"", " NOT NULL", "")& IF(H11<>"", ",", IF(B12<>"", ",", "") )& " -- "&B11 )} -> ERROR_MESSAGE VARCHAR(100), -- エラーメッセージ
A13: =A12+1 -> 6 | B13: 紐付け日時 | C13: LINKED_DATE | D13: TIMESTAMP | E13: - | F13: - | L13: {=IF(B12="", IF($L$6="PRIMARY_KEYS", ",PRIMARY KEY ("&_xlfn.TEXTJOIN(", ", TRUE, $C$8)&")" & CHAR(10) & ");", ");" ), " "&C12&" "&D12& _xlfn.IFS( E12="-", "", OR(D12="TIMESTAMP", D12="SMALLINT"), E12&IF(F12<>"-", ","&F12, ""), TRUE, "("&E12&IF(F12<>"-", ","&F12, "")&")" )& IF(G12<>"", " NOT NULL", "")& IF(H12<>"", ",", IF(B13<>"", ",", "") )& " -- "&B12 )} -> LINKED_ERROR_MESSAGE VARCHAR(100), -- 紐付けエラーメッセージ
A14: =A13+1 -> 7 | B14: 作成者 | C14: CREATED_BY | D14: VARCHAR | E14: 50 | F14: - | G14: 〇 | L14: {=IF(B13="", IF($L$6="PRIMARY_KEYS", ",PRIMARY KEY ("&_xlfn.TEXTJOIN(", ", TRUE, $C$8)&")" & CHAR(10) & ");", ");" ), " "&C13&" "&D13& _xlfn.IFS( E13="-", "", OR(D13="TIMESTAMP", D13="SMALLINT"), E13&IF(F13<>"-", ","&F13, ""), TRUE, "("&E13&IF(F13<>"-", ","&F13, "")&")" )& IF(G13<>"", " NOT NULL", "")& IF(H13<>"", ",", IF(B14<>"", ",", "") )& " -- "&B13 )} -> LINKED_DATE TIMESTAMP, -- 紐付け日時
A15: =A14+1 -> 8 | B15: 作成日時 | C15: CREATED_AT | D15: TIMESTAMP | E15: - | F15: - | G15: 〇 | I15: レコード作成日時 | L15: {=IF(B14="", IF($L$6="PRIMARY_KEYS", ",PRIMARY KEY ("&_xlfn.TEXTJOIN(", ", TRUE, $C$8)&")" & CHAR(10) & ");", ");" ), " "&C14&" "&D14& _xlfn.IFS( E14="-", "", OR(D14="TIMESTAMP", D14="SMALLINT"), E14&IF(F14<>"-", ","&F14, ""), TRUE, "("&E14&IF(F14<>"-", ","&F14, "")&")" )& IF(G14<>"", " NOT NULL", "")& IF(H14<>"", ",", IF(B15<>"", ",", "") )& " -- "&B14 )} -> CREATED_BY VARCHAR(50) NOT NULL, -- 作成者
A16: =A15+1 -> 9 | B16: 更新者 | C16: UPDATED_BY | D16: VARCHAR | E16: 50 | F16: - | L16: {=IF(B15="", IF($L$6="PRIMARY_KEYS", ",PRIMARY KEY ("&_xlfn.TEXTJOIN(", ", TRUE, $C$8)&")" & CHAR(10) & ");", ");" ), " "&C15&" "&D15& _xlfn.IFS( E15="-", "", OR(D15="TIMESTAMP", D15="SMALLINT"), E15&IF(F15<>"-", ","&F15, ""), TRUE, "("&E15&IF(F15<>"-", ","&F15, "")&")" )& IF(G15<>"", " NOT NULL", "")& IF(H15<>"", ",", IF(B16<>"", ",", "") )& " -- "&B15 )} -> CREATED_AT TIMESTAMP NOT NULL, -- 作成日時
A17: =A16+1 -> 10 | B17: 更新日時 | C17: UPDATED_AT | D17: TIMESTAMP | E17: - | F17: - | I17: レコード更新日時 | L17: {=IF(B16="", IF($L$6="PRIMARY_KEYS", ",PRIMARY KEY ("&_xlfn.TEXTJOIN(", ", TRUE, $C$8)&")" & CHAR(10) & ");", ");" ), " "&C16&" "&D16& _xlfn.IFS( E16="-", "", OR(D16="TIMESTAMP", D16="SMALLINT"), E16&IF(F16<>"-", ","&F16, ""), TRUE, "("&E16&IF(F16<>"-", ","&F16, "")&")" )& IF(G16<>"", " NOT NULL", "")& IF(H16<>"", ",", IF(B17<>"", ",", "") )& " -- "&B16 )} -> UPDATED_BY VARCHAR(50), -- 更新者
L18: {=IF(B17="", IF($L$6="PRIMARY_KEYS", ",PRIMARY KEY ("&_xlfn.TEXTJOIN(", ", TRUE, $C$8)&")" & CHAR(10) & ");", ");" ), " "&C17&" "&D17& _xlfn.IFS( E17="-", "", OR(D17="TIMESTAMP", D17="SMALLINT"), E17&IF(F17<>"-", ","&F17, ""), TRUE, "("&E17&IF(F17<>"-", ","&F17, "")&")" )& IF(G17<>"", " NOT NULL", "")& IF(H17<>"", ",", IF(B18<>"", ",", "") )& " -- "&B17 )} -> UPDATED_AT TIMESTAMP -- 更新日時
L19: {=IF(B18="", IF($L$6="PRIMARY_KEYS", ",PRIMARY KEY ("&_xlfn.TEXTJOIN(", ", TRUE, $C$8)&")" & CHAR(10) & ");", ");" ), " "&C18&" "&D18& _xlfn.IFS( E18="-", "", OR(D18="TIMESTAMP", D18="SMALLINT"), E18&IF(F18<>"-", ","&F18, ""), TRUE, "("&E18&IF(F18<>"-", ","&F18, "")&")" )& IF(G18<>"", " NOT NULL", "")& IF(H18<>"", ",", IF(B19<>"", ",", "") )& " -- "&B18 )} -> ,PRIMARY KEY (SUPPLY_POINT_NUMBER) );
L22: ="COMMENT ON TABLE db_corp." & $A$5 & " IS '" & $A$3 & "';" -> COMMENT ON TABLE db_corp.T_30MIN_IMPORT_MNG IS '30分値取込管理';
L23: ="COMMENT ON COLUMN db_corp." & $A$5&"."&C8&" IS '" &B8&"';" -> COMMENT ON COLUMN db_corp.T_30MIN_IMPORT_MNG.SUPPLY_POINT_NUMBER IS '供給地点特定番号(FK)';
L24: ="COMMENT ON COLUMN db_corp." & $A$5&"."&C9&" IS '" &B9&"';" -> COMMENT ON COLUMN db_corp.T_30MIN_IMPORT_MNG.TARGET_YEAR_MONTH IS '対象年月';
L25: ="COMMENT ON COLUMN db_corp." & $A$5&"."&C10&" IS '" &B10&"';" -> COMMENT ON COLUMN db_corp.T_30MIN_IMPORT_MNG.CREATE_STATUS IS '作成状態';
L26: ="COMMENT ON COLUMN db_corp." & $A$5&"."&C11&" IS '" &B11&"';" -> COMMENT ON COLUMN db_corp.T_30MIN_IMPORT_MNG.ERROR_MESSAGE IS 'エラーメッセージ';
L27: ="COMMENT ON COLUMN db_corp." & $A$5&"."&C12&" IS '" &B12&"';" -> COMMENT ON COLUMN db_corp.T_30MIN_IMPORT_MNG.LINKED_ERROR_MESSAGE IS '紐付けエラーメッセージ';
L28: ="COMMENT ON COLUMN db_corp." & $A$5&"."&C13&" IS '" &B13&"';" -> COMMENT ON COLUMN db_corp.T_30MIN_IMPORT_MNG.LINKED_DATE IS '紐付け日時';
L29: ="COMMENT ON COLUMN db_corp." & $A$5&"."&C14&" IS '" &B14&"';" -> COMMENT ON COLUMN db_corp.T_30MIN_IMPORT_MNG.CREATED_BY IS '作成者';
L30: ="COMMENT ON COLUMN db_corp." & $A$5&"."&C15&" IS '" &B15&"';" -> COMMENT ON COLUMN db_corp.T_30MIN_IMPORT_MNG.CREATED_AT IS '作成日時';
L31: ="COMMENT ON COLUMN db_corp." & $A$5&"."&C16&" IS '" &B16&"';" -> COMMENT ON COLUMN db_corp.T_30MIN_IMPORT_MNG.UPDATED_BY IS '更新者';
L32: ="COMMENT ON COLUMN db_corp." & $A$5&"."&C17&" IS '" &B17&"';" -> COMMENT ON COLUMN db_corp.T_30MIN_IMPORT_MNG.UPDATED_AT IS '更新日時';
L33: ="COMMENT ON COLUMN db_corp." & $A$5&"."&C20&" IS '" &B20&"';" -> COMMENT ON COLUMN db_corp.T_30MIN_IMPORT_MNG. IS '';
L34: ="COMMENT ON COLUMN db_corp." & $A$5&"."&C21&" IS '" &B21&"';" -> COMMENT ON COLUMN db_corp.T_30MIN_IMPORT_MNG. IS '';
L35: ="COMMENT ON COLUMN db_corp." & $A$5&"."&C22&" IS '" &B22&"';" -> COMMENT ON COLUMN db_corp.T_30MIN_IMPORT_MNG. IS '';
L36: ="COMMENT ON COLUMN db_corp." & $A$5&"."&C23&" IS '" &B23&"';" -> COMMENT ON COLUMN db_corp.T_30MIN_IMPORT_MNG. IS '';
L37: ="COMMENT ON COLUMN db_corp." & $A$5&"."&C24&" IS '" &B24&"';" -> COMMENT ON COLUMN db_corp.T_30MIN_IMPORT_MNG. IS '';
L38: ="COMMENT ON COLUMN db_corp." & $A$5&"."&C25&" IS '" &B25&"';" -> COMMENT ON COLUMN db_corp.T_30MIN_IMPORT_MNG. IS '';

Sheet 過去分ARVEお客さま情報
D1: =修正履歴!E7 -> 2026/12/21
A2: テーブル名（日本語） | D2: システム名 | I2: 作成者 | J2: 承認者 | K2: 作成日
A3: 過去分ARVEお客さま情報 | D3: CNレポート作成アプリ「LecMoc」
A4: テーブル名（英語） | D4: スキーマ | I4: 更新者 | J4: 承認者 | K4: 更新日
A5: T_HISTORICAL_ARVE_CUSTOMER_INFO | D5: DB_CORP
A6: ARVEから受領するテーブルのため、項目名および型桁はARVEに合わせ定義する ※青字のものはそのまま登録する項目 | L6: PRIMARY_KEYS
A7: No | B7: 論理名 | C7: 物理名 | D7: 型 | E7: 長さ | F7: 精度 | G7: 必須 | H7: 主キー（PK） | I7: 備考 | L7: ="drop TABLE IF EXISTS db_corp."&A5&" CASCADE;" -> drop TABLE IF EXISTS db_corp.T_HISTORICAL_ARVE_CUSTOMER_INFO CASCADE;
A8: 1 | B8: 供給地点特定番号(FK) | C8: CMN_SupplyPointSpecificNum__c | D8: VARCHAR | E8: 22 | F8: - | G8: 〇 | H8: 1 | L8: ="CREATE TABLE IF NOT EXISTS db_corp."&A5&" (" -> CREATE TABLE IF NOT EXISTS db_corp.T_HISTORICAL_ARVE_CUSTOMER_INFO (
A9: =A8+1 -> 2 | B9: 取得年月 | C9: ACQUISITION_YEAR_MONTH | D9: VARCHAR | E9: 6 | F9: - | G9: 〇 | H9: 2 | L9: {=IF(B8="", IF($L$6="PRIMARY_KEYS", ",PRIMARY KEY ("&_xlfn.TEXTJOIN(", ", TRUE, $C$8)&")" & CHAR(10) & ");", ");" ), " "&C8&" "&D8& _xlfn.IFS( E8="-", "", OR(D8="TIMESTAMP", D8="SMALLINT"), E8&IF(F8<>"-", ","&F8, ""), TRUE, "("&E8&IF(F8<>"-", ","&F8, "")&")" )& IF(G8<>"", " NOT NULL", "")& IF(H8<>"", ",", IF(B9<>"", ",", "") )& " -- "&B8 )} -> CMN_SupplyPointSpecificNum__c VARCHAR(22) NOT NULL, -- 供給地点特定番号(FK)
A10: =A9+1 -> 3 | B10: 業務種別 | C10: CMN_BusinessType__c | D10: VARCHAR | E10: 4 | F10: - | I10: 「2：高圧」のみ抽出 | L10: {=IF(B9="", IF($L$6="PRIMARY_KEYS", ",PRIMARY KEY ("&_xlfn.TEXTJOIN(", ", TRUE, $C$8)&")" & CHAR(10) & ");", ");" ), " "&C9&" "&D9& _xlfn.IFS( E9="-", "", OR(D9="TIMESTAMP", D9="SMALLINT"), E9&IF(F9<>"-", ","&F9, ""), TRUE, "("&E9&IF(F9<>"-", ","&F9, "")&")" )& IF(G9<>"", " NOT NULL", "")& IF(H9<>"", ",", IF(B10<>"", ",", "") )& " -- "&B9 )} -> ACQUISITION_YEAR_MONTH VARCHAR(6) NOT NULL, -- 取得年月
A11: =A10+1 -> 4 | B11: お客さま番号 | C11: CMN_OldCustomerNum__c | D11: VARCHAR | E11: 16 | F11: - | L11: {=IF(B10="", IF($L$6="PRIMARY_KEYS", ",PRIMARY KEY ("&_xlfn.TEXTJOIN(", ", TRUE, $C$8)&")" & CHAR(10) & ");", ");" ), " "&C10&" "&D10& _xlfn.IFS( E10="-", "", OR(D10="TIMESTAMP", D10="SMALLINT"), E10&IF(F10<>"-", ","&F10, ""), TRUE, "("&E10&IF(F10<>"-", ","&F10, "")&")" )& IF(G10<>"", " NOT NULL", "")& IF(H10<>"", ",", IF(B11<>"", ",", "") )& " -- "&B10 )} -> CMN_BusinessType__c VARCHAR(4), -- 業務種別
A12: =A11+1 -> 5 | B12: 契約電力(kW) | C12: CMN_PowerContract__c | D12: VARCHAR | E12: 10 | F12: - | L12: {=IF(B11="", IF($L$6="PRIMARY_KEYS", ",PRIMARY KEY ("&_xlfn.TEXTJOIN(", ", TRUE, $C$8)&")" & CHAR(10) & ");", ");" ), " "&C11&" "&D11& _xlfn.IFS( E11="-", "", OR(D11="TIMESTAMP", D11="SMALLINT"), E11&IF(F11<>"-", ","&F11, ""), TRUE, "("&E11&IF(F11<>"-", ","&F11, "")&")" )& IF(G11<>"", " NOT NULL", "")& IF(H11<>"", ",", IF(B12<>"", ",", "") )& " -- "&B11 )} -> CMN_OldCustomerNum__c VARCHAR(16), -- お客さま番号
A13: =A12+1 -> 6 | B13: 契約種別 | C13: CMN_ContractType__c | D13: VARCHAR | E13: 1300 | F13: - | L13: {=IF(B12="", IF($L$6="PRIMARY_KEYS", ",PRIMARY KEY ("&_xlfn.TEXTJOIN(", ", TRUE, $C$8)&")" & CHAR(10) & ");", ");" ), " "&C12&" "&D12& _xlfn.IFS( E12="-", "", OR(D12="TIMESTAMP", D12="SMALLINT"), E12&IF(F12<>"-", ","&F12, ""), TRUE, "("&E12&IF(F12<>"-", ","&F12, "")&")" )& IF(G12<>"", " NOT NULL", "")& IF(H12<>"", ",", IF(B13<>"", ",", "") )& " -- "&B12 )} -> CMN_PowerContract__c VARCHAR(10), -- 契約電力(kW)
A14: =A13+1 -> 7 | B14: 契約場所_住所 | C14: CMN_DemandLocationAddress__c | D14: VARCHAR | E14: 1300 | F14: - | L14: {=IF(B13="", IF($L$6="PRIMARY_KEYS", ",PRIMARY KEY ("&_xlfn.TEXTJOIN(", ", TRUE, $C$8)&")" & CHAR(10) & ");", ");" ), " "&C13&" "&D13& _xlfn.IFS( E13="-", "", OR(D13="TIMESTAMP", D13="SMALLINT"), E13&IF(F13<>"-", ","&F13, ""), TRUE, "("&E13&IF(F13<>"-", ","&F13, "")&")" )& IF(G13<>"", " NOT NULL", "")& IF(H13<>"", ",", IF(B14<>"", ",", "") )& " -- "&B13 )} -> CMN_ContractType__c VARCHAR(1300), -- 契約種別
A15: =A14+1 -> 8 | B15: 紐づけ元契約商品 | C15: CMN_LinkedSourceContractItem__c | D15: VARCHAR | E15: 18 | F15: - | I15: 「空白」のみ抽出 | L15: {=IF(B14="", IF($L$6="PRIMARY_KEYS", ",PRIMARY KEY ("&_xlfn.TEXTJOIN(", ", TRUE, $C$8)&")" & CHAR(10) & ");", ");" ), " "&C14&" "&D14& _xlfn.IFS( E14="-", "", OR(D14="TIMESTAMP", D14="SMALLINT"), E14&IF(F14<>"-", ","&F14, ""), TRUE, "("&E14&IF(F14<>"-", ","&F14, "")&")" )& IF(G14<>"", " NOT NULL", "")& IF(H14<>"", ",", IF(B15<>"", ",", "") )& " -- "&B14 )} -> CMN_DemandLocationAddress__c VARCHAR(1300), -- 契約場所_住所
A16: =A15+1 -> 9 | B16: 旧契約需要場所 | C16: CMN_OldJuyobasho__c | D16: VARCHAR | E16: 18 | F16: - | L16: {=IF(B15="", IF($L$6="PRIMARY_KEYS", ",PRIMARY KEY ("&_xlfn.TEXTJOIN(", ", TRUE, $C$8)&")" & CHAR(10) & ");", ");" ), " "&C15&" "&D15& _xlfn.IFS( E15="-", "", OR(D15="TIMESTAMP", D15="SMALLINT"), E15&IF(F15<>"-", ","&F15, ""), TRUE, "("&E15&IF(F15<>"-", ","&F15, "")&")" )& IF(G15<>"", " NOT NULL", "")& IF(H15<>"", ",", IF(B16<>"", ",", "") )& " -- "&B15 )} -> CMN_LinkedSourceContractItem__c VARCHAR(18), -- 紐づけ元契約商品
A17: =A16+1 -> 10 | B17: 計量日 | C17: CMN_AcutualMaterReadingDate__c | D17: VARCHAR | E17: 2 | F17: - | I17: 1;2;3;4;5;6;8;9;10;11;12;13;15;16;17;18;19;20;22;23;24;25;26;27;28;29;30;31 | L17: {=IF(B16="", IF($L$6="PRIMARY_KEYS", ",PRIMARY KEY ("&_xlfn.TEXTJOIN(", ", TRUE, $C$8)&")" & CHAR(10) & ");", ");" ), " "&C16&" "&D16& _xlfn.IFS( E16="-", "", OR(D16="TIMESTAMP", D16="SMALLINT"), E16&IF(F16<>"-", ","&F16, ""), TRUE, "("&E16&IF(F16<>"-", ","&F16, "")&")" )& IF(G16<>"", " NOT NULL", "")& IF(H16<>"", ",", IF(B17<>"", ",", "") )& " -- "&B16 )} -> CMN_OldJuyobasho__c VARCHAR(18), -- 旧契約需要場所
A18: =A17+1 -> 11 | B18: 契約終了日 | C18: CMN_ContractEndDate2__c | D18: VARCHAR | E18: 10 | F18: - | I18: YYYY/MM/DD | L18: {=IF(B17="", IF($L$6="PRIMARY_KEYS", ",PRIMARY KEY ("&_xlfn.TEXTJOIN(", ", TRUE, $C$8)&")" & CHAR(10) & ");", ");" ), " "&C17&" "&D17& _xlfn.IFS( E17="-", "", OR(D17="TIMESTAMP", D17="SMALLINT"), E17&IF(F17<>"-", ","&F17, ""), TRUE, "("&E17&IF(F17<>"-", ","&F17, "")&")" )& IF(G17<>"", " NOT NULL", "")& IF(H17<>"", ",", IF(B18<>"", ",", "") )& " -- "&B17 )} -> CMN_AcutualMaterReadingDate__c VARCHAR(2), -- 計量日
A19: =A18+1 -> 12 | B19: 契約状態 | C19: CMN_ContractStatus__c | D19: VARCHAR | E19: 5 | F19: - | I19: 「契約中」のみ抽出 | L19: {=IF(B18="", IF($L$6="PRIMARY_KEYS", ",PRIMARY KEY ("&_xlfn.TEXTJOIN(", ", TRUE, $C$8)&")" & CHAR(10) & ");", ");" ), " "&C18&" "&D18& _xlfn.IFS( E18="-", "", OR(D18="TIMESTAMP", D18="SMALLINT"), E18&IF(F18<>"-", ","&F18, ""), TRUE, "("&E18&IF(F18<>"-", ","&F18, "")&")" )& IF(G18<>"", " NOT NULL", "")& IF(H18<>"", ",", IF(B19<>"", ",", "") )& " -- "&B18 )} -> CMN_ContractEndDate2__c VARCHAR(10), -- 契約終了日
A20: =A19+1 -> 13 | B20: 契約場所_名義(姓)＿契約場所_名義(名) | C20: CMN_DemandLocationFullName_Ref__c | D20: VARCHAR | E20: 1300 | F20: - | L20: {=IF(B19="", IF($L$6="PRIMARY_KEYS", ",PRIMARY KEY ("&_xlfn.TEXTJOIN(", ", TRUE, $C$8)&")" & CHAR(10) & ");", ");" ), " "&C19&" "&D19& _xlfn.IFS( E19="-", "", OR(D19="TIMESTAMP", D19="SMALLINT"), E19&IF(F19<>"-", ","&F19, ""), TRUE, "("&E19&IF(F19<>"-", ","&F19, "")&")" )& IF(G19<>"", " NOT NULL", "")& IF(H19<>"", ",", IF(B20<>"", ",", "") )& " -- "&B19 )} -> CMN_ContractStatus__c VARCHAR(5), -- 契約状態
A21: =A20+1 -> 14 | B21: 企業ID | C21: CMN_KigyoID_Fk__c | D21: VARCHAR | E21: 1300 | F21: - | L21: {=IF(B20="", IF($L$6="PRIMARY_KEYS", ",PRIMARY KEY ("&_xlfn.TEXTJOIN(", ", TRUE, $C$8)&")" & CHAR(10) & ");", ");" ), " "&C20&" "&D20& _xlfn.IFS( E20="-", "", OR(D20="TIMESTAMP", D20="SMALLINT"), E20&IF(F20<>"-", ","&F20, ""), TRUE, "("&E20&IF(F20<>"-", ","&F20, "")&")" )& IF(G20<>"", " NOT NULL", "")& IF(H20<>"", ",", IF(B21<>"", ",", "") )& " -- "&B20 )} -> CMN_DemandLocationFullName_Ref__c VARCHAR(1300), -- 契約場所_名義(姓)＿契約場所_名義(名)
A22: =A21+1 -> 15 | B22: 営業窓口アカウント | C22: CMN_SalesContactAccount__c | D22: VARCHAR | E22: 1300 | F22: - | L22: {=IF(B21="", IF($L$6="PRIMARY_KEYS", ",PRIMARY KEY ("&_xlfn.TEXTJOIN(", ", TRUE, $C$8)&")" & CHAR(10) & ");", ");" ), " "&C21&" "&D21& _xlfn.IFS( E21="-", "", OR(D21="TIMESTAMP", D21="SMALLINT"), E21&IF(F21<>"-", ","&F21, ""), TRUE, "("&E21&IF(F21<>"-", ","&F21, "")&")" )& IF(G21<>"", " NOT NULL", "")& IF(H21<>"", ",", IF(B22<>"", ",", "") )& " -- "&B21 )} -> CMN_KigyoID_Fk__c VARCHAR(1300), -- 企業ID
A23: =A22+1 -> 16 | B23: 実績責任担当者 | C23: CMN_User_PerformanceAccountAbilityRep__c | D23: VARCHAR | E23: 1300 | F23: - | L23: {=IF(B22="", IF($L$6="PRIMARY_KEYS", ",PRIMARY KEY ("&_xlfn.TEXTJOIN(", ", TRUE, $C$8)&")" & CHAR(10) & ");", ");" ), " "&C22&" "&D22& _xlfn.IFS( E22="-", "", OR(D22="TIMESTAMP", D22="SMALLINT"), E22&IF(F22<>"-", ","&F22, ""), TRUE, "("&E22&IF(F22<>"-", ","&F22, "")&")" )& IF(G22<>"", " NOT NULL", "")& IF(H22<>"", ",", IF(B23<>"", ",", "") )& " -- "&B22 )} -> CMN_SalesContactAccount__c VARCHAR(1300), -- 営業窓口アカウント
A24: =A23+1 -> 17 | B24: 組織ID（FK） | C24: ORG_ID | D24: VARCHAR | E24: 20 | F24: - | I24: 利用者組織情報テーブルから紐づけて登録 | L24: {=IF(B23="", IF($L$6="PRIMARY_KEYS", ",PRIMARY KEY ("&_xlfn.TEXTJOIN(", ", TRUE, $C$8)&")" & CHAR(10) & ");", ");" ), " "&C23&" "&D23& _xlfn.IFS( E23="-", "", OR(D23="TIMESTAMP", D23="SMALLINT"), E23&IF(F23<>"-", ","&F23, ""), TRUE, "("&E23&IF(F23<>"-", ","&F23, "")&")" )& IF(G23<>"", " NOT NULL", "")& IF(H23<>"", ",", IF(B24<>"", ",", "") )& " -- "&B23 )} -> CMN_User_PerformanceAccountAbilityRep__c VARCHAR(1300), -- 実績責任担当者
